Workbook

Sheet Leia-me
A1: Como usar esta planilha
A3: Azul | B3: entrada — pode mudar
A4: Preto | B4: fórmula — não digite em cima
A5: Verde | B5: valor puxado da aba Parametros
A6: Amarelo | B6: cota medida na malha STL e AINDA NÃO conferida em peça física, ou célula de escolha do usuário
A8: Parametros | B8: as cotas do sistema. Três fitas no showroom validam ou derrubam tudo: passo vertical de uma baia de 270 (esperado 261,88), profundidade externa com painel 200 (285,3), sobra da peça L por lado (21,62).
A9: Comprimento | B9: comprimento externo para cada ripa × N vãos, com e sem coroa
A10: Profundidade | B10: as três profundidades possíveis — uma por módulo, sem afinar por prateleira
A11: Altura | B11: altura total por contagem de baias de 270 e 513, sem e com coroa
A12: Pilha | B12: calculadora: digite a sequência de baias e leia a face de cada prateleira e a zona do varejo
A13: Paineis | B13: a grade de 12 e a regra da proporção que deixa 7
A14: Modulos | B14: as 126 combinações painel × N vãos com comprimento, profundidade, área de piso e contagem de peças; filtre pela linha 6

Sheet Parametros
A1: Nitron Mob — parâmetros do sistema
A2: Células azuis são entradas. As amarelas vieram da malha STL e ainda não foram conferidas com trena: mude aqui e tudo recalcula.
A4: Parâmetro | B4: Símbolo | C4: Valor (mm) | D4: Origem | E4: Como conferir
A5: Profundidade do encaixe da ripa no nó | B5: ENC | C5: 40.6 | D5: malha STL | E5: ripa dentro da trizeta até o fundo
A6: Trizeta · eixo do comprimento | B6: NOX | C6: 61.61 | D6: malha STL | E6: largura externa da trizeta
A7: Cruzeta · eixo do comprimento | B7: NOXC | C7: 101.3 | D7: malha STL | E7: largura externa da cruzeta
A8: Trizeta · eixo da profundidade | B8: NOY | C8: 83.23 | D8: malha STL | E8: PROFUNDIDADE externa com painel de 200 deve dar 285,3
A9: Trizeta · eixo vertical (passo do nó) | B9: NOZ | C9: 73.08 | D9: malha STL | E9: PASSO VERTICAL de uma baia de 270 deve dar 261,88 (rival: 335,0)
A10: Peça L · sobra por lado (coroa) | B10: NOL | C10: 21.92 | D10: malha STL | E10: SOBRA da peça L por lado deve dar 21,62
A11: Pé exposto abaixo do primeiro nó | B11: PE | C11: 19.4 | D11: malha STL | E11: do chão à face inferior da trizeta
A12: Espessura do painel (pinus) | B12: PANT | C12: 15 | D12: informado | E12: paquímetro no painel
A13: Ripa consome no total (2 × ENC) | B13: CONSOME | C13: =2*C5 -> 81.2 | D13: fórmula
A14: Regra de proporção do painel · mínimo | B14: RAZ_MIN | C14: 1.3 | D14: decisão | E14: comprimento ÷ largura
A15: Regra de proporção do painel · máximo | B15: RAZ_MAX | C15: 2.6 | D15: decisão | E15: comprimento ÷ largura
A18: Ripas de LARGURA (fixam a profundidade — uma por módulo)
A19: Código | B19: Largura (mm) | C19: Painel (largura)
A20: BLA-01-AC | B20: 200 | C20: 200
A21: BLA-03-AC | B21: 287 | C21: 300
A22: PSC-02 | B22: 415 | C22: 460
A24: Ripas de COMPRIMENTO (uma por vão)
A25: Código | B25: Comprimento (mm) | C25: Painel (comprimento)
A26: PSC-01 | B26: 315 | C26: 360
A27: PSC-02 | B27: 415 | C27: 450
A28: PSC-03 | B28: 595 | C28: 634
A29: PSC-04 | B29: 717 | C29: 754
A31: Ripas de ALTURA (uma por baia; a peça L usa a mesma ripa como coroa)
A32: Código | B32: Altura (mm)
A33: BAL-02-AC | B33: 270
A34: PSA-05 | B34: 513
A36: Fonte: malhas STL das cinco peças (trizeta, cruzeta, peça L, porta-haste, tampa) medidas em 04/09/2026; ripas e painéis conforme lista fixada pelo marketing em 05/09/2026. Corroboração: ripas 315/415/595/717 + 42,02 dão 357/457/637/759 contra painéis 360/450/634/754 — quatro em quatro dentro de ±7 mm.

Sheet Comprimento
A1: Comprimento externo do módulo (mm)
A2: Fórmula: 2 × NOX + (N − 1) × NOXC + N × (ripa − CONSOME). A coroa (peça L) acrescenta 2 × NOL de cada lado do topo — não muda a base.
A4: N vãos | B4: PSC-01 · 315 | C4: PSC-02 · 415 | D4: PSC-03 · 595 | E4: PSC-04 · 717 | G4: PSC-01 com coroa | H4: PSC-02 com coroa | I4: PSC-03 com coroa | J4: PSC-04 com coroa
A5: painel → | B5: 360 mm | C5: 450 mm | D5: 634 mm | E5: 754 mm
A6: 1 | B6: =2*Parametros!$C$6+(A6-1)*Parametros!$C$7+A6*(Parametros!$B$26-Parametros!$C$13) -> 357.02 | C6: =2*Parametros!$C$6+(A6-1)*Parametros!$C$7+A6*(Parametros!$B$27-Parametros!$C$13) -> 457.02 | D6: =2*Parametros!$C$6+(A6-1)*Parametros!$C$7+A6*(Parametros!$B$28-Parametros!$C$13) -> 637.02 | E6: =2*Parametros!$C$6+(A6-1)*Parametros!$C$7+A6*(Parametros!$B$29-Parametros!$C$13) -> 759.02 | G6: =B6+2*Parametros!$C$10 -> 400.86 | H6: =C6+2*Parametros!$C$10 -> 500.86 | I6: =D6+2*Parametros!$C$10 -> 680.86 | J6: =E6+2*Parametros!$C$10 -> 802.86
A7: 2 | B7: =2*Parametros!$C$6+(A7-1)*Parametros!$C$7+A7*(Parametros!$B$26-Parametros!$C$13) -> 692.12 | C7: =2*Parametros!$C$6+(A7-1)*Parametros!$C$7+A7*(Parametros!$B$27-Parametros!$C$13) -> 892.12 | D7: =2*Parametros!$C$6+(A7-1)*Parametros!$C$7+A7*(Parametros!$B$28-Parametros!$C$13) -> 1252.12 | E7: =2*Parametros!$C$6+(A7-1)*Parametros!$C$7+A7*(Parametros!$B$29-Parametros!$C$13) -> 1496.12 | G7: =B7+2*Parametros!$C$10 -> 735.96 | H7: =C7+2*Parametros!$C$10 -> 935.96 | I7: =D7+2*Parametros!$C$10 -> 1295.96 | J7: =E7+2*Parametros!$C$10 -> 1539.96
A8: 3 | B8: =2*Parametros!$C$6+(A8-1)*Parametros!$C$7+A8*(Parametros!$B$26-Parametros!$C$13) -> 1027.22 | C8: =2*Parametros!$C$6+(A8-1)*Parametros!$C$7+A8*(Parametros!$B$27-Parametros!$C$13) -> 1327.22 | D8: =2*Parametros!$C$6+(A8-1)*Parametros!$C$7+A8*(Parametros!$B$28-Parametros!$C$13) -> 1867.22 | E8: =2*Parametros!$C$6+(A8-1)*Parametros!$C$7+A8*(Parametros!$B$29-Parametros!$C$13) -> 2233.22 | G8: =B8+2*Parametros!$C$10 -> 1071.06 | H8: =C8+2*Parametros!$C$10 -> 1371.06 | I8: =D8+2*Parametros!$C$10 -> 1911.06 | J8: =E8+2*Parametros!$C$10 -> 2277.06
A9: 4 | B9: =2*Parametros!$C$6+(A9-1)*Parametros!$C$7+A9*(Parametros!$B$26-Parametros!$C$13) -> 1362.32 | C9: =2*Parametros!$C$6+(A9-1)*Parametros!$C$7+A9*(Parametros!$B$27-Parametros!$C$13) -> 1762.32 | D9: =2*Parametros!$C$6+(A9-1)*Parametros!$C$7+A9*(Parametros!$B$28-Parametros!$C$13) -> 2482.32 | E9: =2*Parametros!$C$6+(A9-1)*Parametros!$C$7+A9*(Parametros!$B$29-Parametros!$C$13) -> 2970.32 | G9: =B9+2*Parametros!$C$10 -> 1406.16 | H9: =C9+2*Parametros!$C$10 -> 1806.16 | I9: =D9+2*Parametros!$C$10 -> 2526.16 | J9: =E9+2*Parametros!$C$10 -> 3014.16
A10: 5 | B10: =2*Parametros!$C$6+(A10-1)*Parametros!$C$7+A10*(Parametros!$B$26-Parametros!$C$13) -> 1697.42 | C10: =2*Parametros!$C$6+(A10-1)*Parametros!$C$7+A10*(Parametros!$B$27-Parametros!$C$13) -> 2197.42 | D10: =2*Parametros!$C$6+(A10-1)*Parametros!$C$7+A10*(Parametros!$B$28-Parametros!$C$13) -> 3097.42 | E10: =2*Parametros!$C$6+(A10-1)*Parametros!$C$7+A10*(Parametros!$B$29-Parametros!$C$13) -> 3707.42 | G10: =B10+2*Parametros!$C$10 -> 1741.26 | H10: =C10+2*Parametros!$C$10 -> 2241.26 | I10: =D10+2*Parametros!$C$10 -> 3141.26 | J10: =E10+2*Parametros!$C$10 -> 3751.26
A11: 6 | B11: =2*Parametros!$C$6+(A11-1)*Parametros!$C$7+A11*(Parametros!$B$26-Parametros!$C$13) -> 2032.52 | C11: =2*Parametros!$C$6+(A11-1)*Parametros!$C$7+A11*(Parametros!$B$27-Parametros!$C$13) -> 2632.52 | D11: =2*Parametros!$C$6+(A11-1)*Parametros!$C$7+A11*(Parametros!$B$28-Parametros!$C$13) -> 3712.52 | E11: =2*Parametros!$C$6+(A11-1)*Parametros!$C$7+A11*(Parametros!$B$29-Parametros!$C$13) -> 4444.52 | G11: =B11+2*Parametros!$C$10 -> 2076.36 | H11: =C11+2*Parametros!$C$10 -> 2676.36 | I11: =D11+2*Parametros!$C$10 -> 3756.36 | J11: =E11+2*Parametros!$C$10 -> 4488.36
A12: 7 | B12: =2*Parametros!$C$6+(A12-1)*Parametros!$C$7+A12*(Parametros!$B$26-Parametros!$C$13) -> 2367.62 | C12: =2*Parametros!$C$6+(A12-1)*Parametros!$C$7+A12*(Parametros!$B$27-Parametros!$C$13) -> 3067.62 | D12: =2*Parametros!$C$6+(A12-1)*Parametros!$C$7+A12*(Parametros!$B$28-Parametros!$C$13) -> 4327.62 | E12: =2*Parametros!$C$6+(A12-1)*Parametros!$C$7+A12*(Parametros!$B$29-Parametros!$C$13) -> 5181.62 | G12: =B12+2*Parametros!$C$10 -> 2411.46 | H12: =C12+2*Parametros!$C$10 -> 3111.46 | I12: =D12+2*Parametros!$C$10 -> 4371.46 | J12: =E12+2*Parametros!$C$10 -> 5225.46
A13: 8 | B13: =2*Parametros!$C$6+(A13-1)*Parametros!$C$7+A13*(Parametros!$B$26-Parametros!$C$13) -> 2702.72 | C13: =2*Parametros!$C$6+(A13-1)*Parametros!$C$7+A13*(Parametros!$B$27-Parametros!$C$13) -> 3502.72 | D13: =2*Parametros!$C$6+(A13-1)*Parametros!$C$7+A13*(Parametros!$B$28-Parametros!$C$13) -> 4942.72 | E13: =2*Parametros!$C$6+(A13-1)*Parametros!$C$7+A13*(Parametros!$B$29-Parametros!$C$13) -> 5918.72 | G13: =B13+2*Parametros!$C$10 -> 2746.56 | H13: =C13+2*Parametros!$C$10 -> 3546.56 | I13: =D13+2*Parametros!$C$10 -> 4986.56 | J13: =E13+2*Parametros!$C$10 -> 5962.56
A14: 9 | B14: =2*Parametros!$C$6+(A14-1)*Parametros!$C$7+A14*(Parametros!$B$26-Parametros!$C$13) -> 3037.82 | C14: =2*Parametros!$C$6+(A14-1)*Parametros!$C$7+A14*(Parametros!$B$27-Parametros!$C$13) -> 3937.82 | D14: =2*Parametros!$C$6+(A14-1)*Parametros!$C$7+A14*(Parametros!$B$28-Parametros!$C$13) -> 5557.82 | E14: =2*Parametros!$C$6+(A14-1)*Parametros!$C$7+A14*(Parametros!$B$29-Parametros!$C$13) -> 6655.82 | G14: =B14+2*Parametros!$C$10 -> 3081.66 | H14: =C14+2*Parametros!$C$10 -> 3981.66 | I14: =D14+2*Parametros!$C$10 -> 5601.66 | J14: =E14+2*Parametros!$C$10 -> 6699.66
A15: 10 | B15: =2*Parametros!$C$6+(A15-1)*Parametros!$C$7+A15*(Parametros!$B$26-Parametros!$C$13) -> 3372.92 | C15: =2*Parametros!$C$6+(A15-1)*Parametros!$C$7+A15*(Parametros!$B$27-Parametros!$C$13) -> 4372.92 | D15: =2*Parametros!$C$6+(A15-1)*Parametros!$C$7+A15*(Parametros!$B$28-Parametros!$C$13) -> 6172.92 | E15: =2*Parametros!$C$6+(A15-1)*Parametros!$C$7+A15*(Parametros!$B$29-Parametros!$C$13) -> 7392.92 | G15: =B15+2*Parametros!$C$10 -> 3416.76 | H15: =C15+2*Parametros!$C$10 -> 4416.76 | I15: =D15+2*Parametros!$C$10 -> 6216.76 | J15: =E15+2*Parametros!$C$10 -> 7436.76
A16: 11 | B16: =2*Parametros!$C$6+(A16-1)*Parametros!$C$7+A16*(Parametros!$B$26-Parametros!$C$13) -> 3708.02 | C16: =2*Parametros!$C$6+(A16-1)*Parametros!$C$7+A16*(Parametros!$B$27-Parametros!$C$13) -> 4808.02 | D16: =2*Parametros!$C$6+(A16-1)*Parametros!$C$7+A16*(Parametros!$B$28-Parametros!$C$13) -> 6788.02 | E16: =2*Parametros!$C$6+(A16-1)*Parametros!$C$7+A16*(Parametros!$B$29-Parametros!$C$13) -> 8130.02 | G16: =B16+2*Parametros!$C$10 -> 3751.86 | H16: =C16+2*Parametros!$C$10 -> 4851.86 | I16: =D16+2*Parametros!$C$10 -> 6831.86 | J16: =E16+2*Parametros!$C$10 -> 8173.86
A17: 12 | B17: =2*Parametros!$C$6+(A17-1)*Parametros!$C$7+A17*(Parametros!$B$26-Parametros!$C$13) -> 4043.12 | C17: =2*Parametros!$C$6+(A17-1)*Parametros!$C$7+A17*(Parametros!$B$27-Parametros!$C$13) -> 5243.12 | D17: =2*Parametros!$C$6+(A17-1)*Parametros!$C$7+A17*(Parametros!$B$28-Parametros!$C$13) -> 7403.12 | E17: =2*Parametros!$C$6+(A17-1)*Parametros!$C$7+A17*(Parametros!$B$29-Parametros!$C$13) -> 8867.12 | G17: =B17+2*Parametros!$C$10 -> 4086.96 | H17: =C17+2*Parametros!$C$10 -> 5286.96 | I17: =D17+2*Parametros!$C$10 -> 7446.96 | J17: =E17+2*Parametros!$C$10 -> 8910.96
... A25: 20 | B25: =2*Parametros!$C$6+(A25-1)*Parametros!$C$7+A25*(Parametros!$B$26-Parametros!$C$13) -> 6723.92 | C25: =2*Parametros!$C$6+(A25-1)*Parametros!$C$7+A25*(Parametros!$B$27-Parametros!$C$13) -> 8723.92 | D25: =2*Parametros!$C$6+(A25-1)*Parametros!$C$7+A25*(Parametros!$B$28-Parametros!$C$13) -> 12323.92 | E25: =2*Parametros!$C$6+(A25-1)*Parametros!$C$7+A25*(Parametros!$B$29-Parametros!$C$13) -> 14763.92 | G25: =B25+2*Parametros!$C$10 -> 6767.76 | H25: =C25+2*Parametros!$C$10 -> 8767.76 | I25: =D25+2*Parametros!$C$10 -> 12367.76 | J25: =E25+2*Parametros!$C$10 -> 14807.76
A27: Conferência com o showroom: PSC-04 × 18 = 13.290 (parede sul 13.350, folga 60) · PSC-01 × 18 = 6.054 (norte 6.100) · PSC-03 × 11 = 6.788 (fundo 6.873) · PSC-02 × 15 = 6.548 (entrada).

Sheet Profundidade
A1: Profundidade externa do módulo (mm)
A2: Fórmula: ripa de largura + 2 × (NOY − ENC). UMA profundidade por módulo: a ripa de largura fixa a distância entre os postes, e os postes são contínuos.
A4: Ripa de largura | B4: Ripa (mm) | C4: Profundidade externa | D4: Painel (largura) | E4: Sobra do painel por lado | F4: Painel vs. externo
A5: BLA-01-AC | B5: =Parametros!$B$20 -> 200 | C5: =B5+2*(Parametros!$C$8-Parametros!$C$5) -> 285.26 | D5: =Parametros!$C$20 -> 200 | E5: =(D5-B5)/2 -> 0 | F5: =D5-C5 -> -85.26
A6: BLA-03-AC | B6: =Parametros!$B$21 -> 287 | C6: =B6+2*(Parametros!$C$8-Parametros!$C$5) -> 372.26 | D6: =Parametros!$C$21 -> 300 | E6: =(D6-B6)/2 -> 6.5 | F6: =D6-C6 -> -72.26
A7: PSC-02 | B7: =Parametros!$B$22 -> 415 | C7: =B7+2*(Parametros!$C$8-Parametros!$C$5) -> 500.26 | D7: =Parametros!$C$22 -> 460 | E7: =(D7-B7)/2 -> 22.5 | F7: =D7-C7 -> -40.26
A9: O painel apoia nas duas ripas de largura e sobressai (D−B)/2 de cada lado: 0 no de 200, 6,5 no de 300, 22,5 no de 460. Ele nunca alcança a cota externa — o nó sobra 42,63 por lado.
A10: Padrão de varejo para referência: prateleira superior 200–400 mm, base 300–500 mm, gôndola dupla face 813–1.219 mm.

Sheet Altura
A1: Altura externa do módulo por composição de baias (mm)
A2: Fórmula: PE + (n_baias + 1) × NOZ + Σ(ripa − CONSOME). Só as CONTAGENS importam para a altura total; a ORDEM muda as faces (ver aba Pilha). Prateleiras = baias + 1.
A4: SEM coroa — módulo termina na última prateleira
A5: baias de 270 ↓ / baias de 513 → | B5: 0 | C5: 1 | D5: 2 | E5: 3 | F5: 4
A6: 0 | B6: =IF($A6+B$5=0,"",Parametros!$C$11+($A6+B$5+1)*Parametros!$C$9+$A6*(Parametros!$B$33-Parametros!$C$13)+B$5*(Parametros!$B$34-Parametros!$C$13)) | C6: =IF($A6+C$5=0,"",Parametros!$C$11+($A6+C$5+1)*Parametros!$C$9+$A6*(Parametros!$B$33-Parametros!$C$13)+C$5*(Parametros!$B$34-Parametros!$C$13)) -> 597.36 | D6: =IF($A6+D$5=0,"",Parametros!$C$11+($A6+D$5+1)*Parametros!$C$9+$A6*(Parametros!$B$33-Parametros!$C$13)+D$5*(Parametros!$B$34-Parametros!$C$13)) -> 1102.24 | E6: =IF($A6+E$5=0,"",Parametros!$C$11+($A6+E$5+1)*Parametros!$C$9+$A6*(Parametros!$B$33-Parametros!$C$13)+E$5*(Parametros!$B$34-Parametros!$C$13)) -> 1607.12 | F6: =IF($A6+F$5=0,"",Parametros!$C$11+($A6+F$5+1)*Parametros!$C$9+$A6*(Parametros!$B$33-Parametros!$C$13)+F$5*(Parametros!$B$34-Parametros!$C$13)) -> 2112
A7: 1 | B7: =IF($A7+B$5=0,"",Parametros!$C$11+($A7+B$5+1)*Parametros!$C$9+$A7*(Parametros!$B$33-Parametros!$C$13)+B$5*(Parametros!$B$34-Parametros!$C$13)) -> 354.36 | C7: =IF($A7+C$5=0,"",Parametros!$C$11+($A7+C$5+1)*Parametros!$C$9+$A7*(Parametros!$B$33-Parametros!$C$13)+C$5*(Parametros!$B$34-Parametros!$C$13)) -> 859.24 | D7: =IF($A7+D$5=0,"",Parametros!$C$11+($A7+D$5+1)*Parametros!$C$9+$A7*(Parametros!$B$33-Parametros!$C$13)+D$5*(Parametros!$B$34-Parametros!$C$13)) -> 1364.12 | E7: =IF($A7+E$5=0,"",Parametros!$C$11+($A7+E$5+1)*Parametros!$C$9+$A7*(Parametros!$B$33-Parametros!$C$13)+E$5*(Parametros!$B$34-Parametros!$C$13)) -> 1869 | F7: =IF($A7+F$5=0,"",Parametros!$C$11+($A7+F$5+1)*Parametros!$C$9+$A7*(Parametros!$B$33-Parametros!$C$13)+F$5*(Parametros!$B$34-Parametros!$C$13)) -> 2373.88
A8: 2 | B8: =IF($A8+B$5=0,"",Parametros!$C$11+($A8+B$5+1)*Parametros!$C$9+$A8*(Parametros!$B$33-Parametros!$C$13)+B$5*(Parametros!$B$34-Parametros!$C$13)) -> 616.24 | C8: =IF($A8+C$5=0,"",Parametros!$C$11+($A8+C$5+1)*Parametros!$C$9+$A8*(Parametros!$B$33-Parametros!$C$13)+C$5*(Parametros!$B$34-Parametros!$C$13)) -> 1121.12 | D8: =IF($A8+D$5=0,"",Parametros!$C$11+($A8+D$5+1)*Parametros!$C$9+$A8*(Parametros!$B$33-Parametros!$C$13)+D$5*(Parametros!$B$34-Parametros!$C$13)) -> 1626 | E8: =IF($A8+E$5=0,"",Parametros!$C$11+($A8+E$5+1)*Parametros!$C$9+$A8*(Parametros!$B$33-Parametros!$C$13)+E$5*(Parametros!$B$34-Parametros!$C$13)) -> 2130.88 | F8: =IF($A8+F$5=0,"",Parametros!$C$11+($A8+F$5+1)*Parametros!$C$9+$A8*(Parametros!$B$33-Parametros!$C$13)+F$5*(Parametros!$B$34-Parametros!$C$13)) -> 2635.76
A9: 3 | B9: =IF($A9+B$5=0,"",Parametros!$C$11+($A9+B$5+1)*Parametros!$C$9+$A9*(Parametros!$B$33-Parametros!$C$13)+B$5*(Parametros!$B$34-Parametros!$C$13)) -> 878.12 | C9: =IF($A9+C$5=0,"",Parametros!$C$11+($A9+C$5+1)*Parametros!$C$9+$A9*(Parametros!$B$33-Parametros!$C$13)+C$5*(Parametros!$B$34-Parametros!$C$13)) -> 1383 | D9: =IF($A9+D$5=0,"",Parametros!$C$11+($A9+D$5+1)*Parametros!$C$9+$A9*(Parametros!$B$33-Parametros!$C$13)+D$5*(Parametros!$B$34-Parametros!$C$13)) -> 1887.88 | E9: =IF($A9+E$5=0,"",Parametros!$C$11+($A9+E$5+1)*Parametros!$C$9+$A9*(Parametros!$B$33-Parametros!$C$13)+E$5*(Parametros!$B$34-Parametros!$C$13)) -> 2392.76 | F9: =IF($A9+F$5=0,"",Parametros!$C$11+($A9+F$5+1)*Parametros!$C$9+$A9*(Parametros!$B$33-Parametros!$C$13)+F$5*(Parametros!$B$34-Parametros!$C$13)) -> 2897.64
A10: 4 | B10: =IF($A10+B$5=0,"",Parametros!$C$11+($A10+B$5+1)*Parametros!$C$9+$A10*(Parametros!$B$33-Parametros!$C$13)+B$5*(Parametros!$B$34-Parametros!$C$13)) -> 1140 | C10: =IF($A10+C$5=0,"",Parametros!$C$11+($A10+C$5+1)*Parametros!$C$9+$A10*(Parametros!$B$33-Parametros!$C$13)+C$5*(Parametros!$B$34-Parametros!$C$13)) -> 1644.88 | D10: =IF($A10+D$5=0,"",Parametros!$C$11+($A10+D$5+1)*Parametros!$C$9+$A10*(Parametros!$B$33-Parametros!$C$13)+D$5*(Parametros!$B$34-Parametros!$C$13)) -> 2149.76 | E10: =IF($A10+E$5=0,"",Parametros!$C$11+($A10+E$5+1)*Parametros!$C$9+$A10*(Parametros!$B$33-Parametros!$C$13)+E$5*(Parametros!$B$34-Parametros!$C$13)) -> 2654.64 | F10: =IF($A10+F$5=0,"",Parametros!$C$11+($A10+F$5+1)*Parametros!$C$9+$A10*(Parametros!$B$33-Parametros!$C$13)+F$5*(Parametros!$B$34-Parametros!$C$13)) -> 3159.52
A11: 5 | B11: =IF($A11+B$5=0,"",Parametros!$C$11+($A11+B$5+1)*Parametros!$C$9+$A11*(Parametros!$B$33-Parametros!$C$13)+B$5*(Parametros!$B$34-Parametros!$C$13)) -> 1401.88 | C11: =IF($A11+C$5=0,"",Parametros!$C$11+($A11+C$5+1)*Parametros!$C$9+$A11*(Parametros!$B$33-Parametros!$C$13)+C$5*(Parametros!$B$34-Parametros!$C$13)) -> 1906.76 | D11: =IF($A11+D$5=0,"",Parametros!$C$11+($A11+D$5+1)*Parametros!$C$9+$A11*(Parametros!$B$33-Parametros!$C$13)+D$5*(Parametros!$B$34-Parametros!$C$13)) -> 2411.64 | E11: =IF($A11+E$5=0,"",Parametros!$C$11+($A11+E$5+1)*Parametros!$C$9+$A11*(Parametros!$B$33-Parametros!$C$13)+E$5*(Parametros!$B$34-Parametros!$C$13)) -> 2916.52 | F11: =IF($A11+F$5=0,"",Parametros!$C$11+($A11+F$5+1)*Parametros!$C$9+$A11*(Parametros!$B$33-Parametros!$C$13)+F$5*(Parametros!$B$34-Parametros!$C$13)) -> 3421.4
A12: 6 | B12: =IF($A12+B$5=0,"",Parametros!$C$11+($A12+B$5+1)*Parametros!$C$9+$A12*(Parametros!$B$33-Parametros!$C$13)+B$5*(Parametros!$B$34-Parametros!$C$13)) -> 1663.76 | C12: =IF($A12+C$5=0,"",Parametros!$C$11+($A12+C$5+1)*Parametros!$C$9+$A12*(Parametros!$B$33-Parametros!$C$13)+C$5*(Parametros!$B$34-Parametros!$C$13)) -> 2168.64 | D12: =IF($A12+D$5=0,"",Parametros!$C$11+($A12+D$5+1)*Parametros!$C$9+$A12*(Parametros!$B$33-Parametros!$C$13)+D$5*(Parametros!$B$34-Parametros!$C$13)) -> 2673.52 | E12: =IF($A12+E$5=0,"",Parametros!$C$11+($A12+E$5+1)*Parametros!$C$9+$A12*(Parametros!$B$33-Parametros!$C$13)+E$5*(Parametros!$B$34-Parametros!$C$13)) -> 3178.4 | F12: =IF($A12+F$5=0,"",Parametros!$C$11+($A12+F$5+1)*Parametros!$C$9+$A12*(Parametros!$B$33-Parametros!$C$13)+F$5*(Parametros!$B$34-Parametros!$C$13)) -> 3683.28
A13: 7 | B13: =IF($A13+B$5=0,"",Parametros!$C$11+($A13+B$5+1)*Parametros!$C$9+$A13*(Parametros!$B$33-Parametros!$C$13)+B$5*(Parametros!$B$34-Parametros!$C$13)) -> 1925.64 | C13: =IF($A13+C$5=0,"",Parametros!$C$11+($A13+C$5+1)*Parametros!$C$9+$A13*(Parametros!$B$33-Parametros!$C$13)+C$5*(Parametros!$B$34-Parametros!$C$13)) -> 2430.52 | D13: =IF($A13+D$5=0,"",Parametros!$C$11+($A13+D$5+1)*Parametros!$C$9+$A13*(Parametros!$B$33-Parametros!$C$13)+D$5*(Parametros!$B$34-Parametros!$C$13)) -> 2935.4 | E13: =IF($A13+E$5=0,"",Parametros!$C$11+($A13+E$5+1)*Parametros!$C$9+$A13*(Parametros!$B$33-Parametros!$C$13)+E$5*(Parametros!$B$34-Parametros!$C$13)) -> 3440.28 | F13: =IF($A13+F$5=0,"",Parametros!$C$11+($A13+F$5+1)*Parametros!$C$9+$A13*(Parametros!$B$33-Parametros!$C$13)+F$5*(Parametros!$B$34-Parametros!$C$13)) -> 3945.16
A15: COM coroa de 270 (peça L no topo, ganha um nível sem prateleira — gancheira ou arara)
A16: baias de 270 ↓ / baias de 513 → | B16: 0 | C16: 1 | D16: 2 | E16: 3 | F16: 4
A17: 0 | B17: =IF($A17+B$16=0,"",Parametros!$C$11+($A17+B$16+1)*Parametros!$C$9+$A17*(Parametros!$B$33-Parametros!$C$13)+B$16*(Parametros!$B$34-Parametros!$C$13)+(Parametros!$C$9+Parametros!$B$33-Parametros!$C$13)) | C17: =IF($A17+C$16=0,"",Parametros!$C$11+($A17+C$16+1)*Parametros!$C$9+$A17*(Parametros!$B$33-Parametros!$C$13)+C$16*(Parametros!$B$34-Parametros!$C$13)+(Parametros!$C$9+Parametros!$B$33-Parametros!$C$13)) -> 859.24 | D17: =IF($A17+D$16=0,"",Parametros!$C$11+($A17+D$16+1)*Parametros!$C$9+$A17*(Parametros!$B$33-Parametros!$C$13)+D$16*(Parametros!$B$34-Parametros!$C$13)+(Parametros!$C$9+Parametros!$B$33-Parametros!$C$13)) -> 1364.12 | E17: =IF($A17+E$16=0,"",Parametros!$C$11+($A17+E$16+1)*Parametros!$C$9+$A17*(Parametros!$B$33-Parametros!$C$13)+E$16*(Parametros!$B$34-Parametros!$C$13)+(Parametros!$C$9+Parametros!$B$33-Parametros!$C$13)) -> 1869 | F17: =IF($A17+F$16=0,"",Parametros!$C$11+($A17+F$16+1)*Parametros!$C$9+$A17*(Parametros!$B$33-Parametros!$C$13)+F$16*(Parametros!$B$34-Parametros!$C$13)+(Parametros!$C$9+Parametros!$B$33-Parametros!$C$13)) -> 2373.88
A18: 1 | B18: =IF($A18+B$16=0,"",Parametros!$C$11+($A18+B$16+1)*Parametros!$C$9+$A18*(Parametros!$B$33-Parametros!$C$13)+B$16*(Parametros!$B$34-Parametros!$C$13)+(Parametros!$C$9+Parametros!$B$33-Parametros!$C$13)) -> 616.24 | C18: =IF($A18+C$16=0,"",Parametros!$C$11+($A18+C$16+1)*Parametros!$C$9+$A18*(Parametros!$B$33-Parametros!$C$13)+C$16*(Parametros!$B$34-Parametros!$C$13)+(Parametros!$C$9+Parametros!$B$33-Parametros!$C$13)) -> 1121.12 | D18: =IF($A18+D$16=0,"",Parametros!$C$11+($A18+D$16+1)*Parametros!$C$9+$A18*(Parametros!$B$33-Parametros!$C$13)+D$16*(Parametros!$B$34-Parametros!$C$13)+(Parametros!$C$9+Parametros!$B$33-Parametros!$C$13)) -> 1626 | E18: =IF($A18+E$16=0,"",Parametros!$C$11+($A18+E$16+1)*Parametros!$C$9+$A18*(Parametros!$B$33-Parametros!$C$13)+E$16*(Parametros!$B$34-Parametros!$C$13)+(Parametros!$C$9+Parametros!$B$33-Parametros!$C$13)) -> 2130.88 | F18: =IF($A18+F$16=0,"",Parametros!$C$11+($A18+F$16+1)*Parametros!$C$9+$A18*(Parametros!$B$33-Parametros!$C$13)+F$16*(Parametros!$B$34-Parametros!$C$13)+(Parametros!$C$9+Parametros!$B$33-Parametros!$C$13)) -> 2635.76
A19: 2 | B19: =IF($A19+B$16=0,"",Parametros!$C$11+($A19+B$16+1)*Parametros!$C$9+$A19*(Parametros!$B$33-Parametros!$C$13)+B$16*(Parametros!$B$34-Parametros!$C$13)+(Parametros!$C$9+Parametros!$B$33-Parametros!$C$13)) -> 878.12 | C19: =IF($A19+C$16=0,"",Parametros!$C$11+($A19+C$16+1)*Parametros!$C$9+$A19*(Parametros!$B$33-Parametros!$C$13)+C$16*(Parametros!$B$34-Parametros!$C$13)+(Parametros!$C$9+Parametros!$B$33-Parametros!$C$13)) -> 1383 | D19: =IF($A19+D$16=0,"",Parametros!$C$11+($A19+D$16+1)*Parametros!$C$9+$A19*(Parametros!$B$33-Parametros!$C$13)+D$16*(Parametros!$B$34-Parametros!$C$13)+(Parametros!$C$9+Parametros!$B$33-Parametros!$C$13)) -> 1887.88 | E19: =IF($A19+E$16=0,"",Parametros!$C$11+($A19+E$16+1)*Parametros!$C$9+$A19*(Parametros!$B$33-Parametros!$C$13)+E$16*(Parametros!$B$34-Parametros!$C$13)+(Parametros!$C$9+Parametros!$B$33-Parametros!$C$13)) -> 2392.76 | F19: =IF($A19+F$16=0,"",Parametros!$C$11+($A19+F$16+1)*Parametros!$C$9+$A19*(Parametros!$B$33-Parametros!$C$13)+F$16*(Parametros!$B$34-Parametros!$C$13)+(Parametros!$C$9+Parametros!$B$33-Parametros!$C$13)) -> 2897.64
A20: 3 | B20: =IF($A20+B$16=0,"",Parametros!$C$11+($A20+B$16+1)*Parametros!$C$9+$A20*(Parametros!$B$33-Parametros!$C$13)+B$16*(Parametros!$B$34-Parametros!$C$13)+(Parametros!$C$9+Parametros!$B$33-Parametros!$C$13)) -> 1140 | C20: =IF($A20+C$16=0,"",Parametros!$C$11+($A20+C$16+1)*Parametros!$C$9+$A20*(Parametros!$B$33-Parametros!$C$13)+C$16*(Parametros!$B$34-Parametros!$C$13)+(Parametros!$C$9+Parametros!$B$33-Parametros!$C$13)) -> 1644.88 | D20: =IF($A20+D$16=0,"",Parametros!$C$11+($A20+D$16+1)*Parametros!$C$9+$A20*(Parametros!$B$33-Parametros!$C$13)+D$16*(Parametros!$B$34-Parametros!$C$13)+(Parametros!$C$9+Parametros!$B$33-Parametros!$C$13)) -> 2149.76 | E20: =IF($A20+E$16=0,"",Parametros!$C$11+($A20+E$16+1)*Parametros!$C$9+$A20*(Parametros!$B$33-Parametros!$C$13)+E$16*(Parametros!$B$34-Parametros!$C$13)+(Parametros!$C$9+Parametros!$B$33-Parametros!$C$13)) -> 2654.64 | F20: =IF($A20+F$16=0,"",Parametros!$C$11+($A20+F$16+1)*Parametros!$C$9+$A20*(Parametros!$B$33-Parametros!$C$13)+F$16*(Parametros!$B$34-Parametros!$C$13)+(Parametros!$C$9+Parametros!$B$33-Parametros!$C$13)) -> 3159.52
A21: 4 | B21: =IF($A21+B$16=0,"",Parametros!$C$11+($A21+B$16+1)*Parametros!$C$9+$A21*(Parametros!$B$33-Parametros!$C$13)+B$16*(Parametros!$B$34-Parametros!$C$13)+(Parametros!$C$9+Parametros!$B$33-Parametros!$C$13)) -> 1401.88 | C21: =IF($A21+C$16=0,"",Parametros!$C$11+($A21+C$16+1)*Parametros!$C$9+$A21*(Parametros!$B$33-Parametros!$C$13)+C$16*(Parametros!$B$34-Parametros!$C$13)+(Parametros!$C$9+Parametros!$B$33-Parametros!$C$13)) -> 1906.76 | D21: =IF($A21+D$16=0,"",Parametros!$C$11+($A21+D$16+1)*Parametros!$C$9+$A21*(Parametros!$B$33-Parametros!$C$13)+D$16*(Parametros!$B$34-Parametros!$C$13)+(Parametros!$C$9+Parametros!$B$33-Parametros!$C$13)) -> 2411.64 | E21: =IF($A21+E$16=0,"",Parametros!$C$11+($A21+E$16+1)*Parametros!$C$9+$A21*(Parametros!$B$33-Parametros!$C$13)+E$16*(Parametros!$B$34-Parametros!$C$13)+(Parametros!$C$9+Parametros!$B$33-Parametros!$C$13)) -> 2916.52 | F21: =IF($A21+F$16=0,"",Parametros!$C$11+($A21+F$16+1)*Parametros!$C$9+$A21*(Parametros!$B$33-Parametros!$C$13)+F$16*(Parametros!$B$34-Parametros!$C$13)+(Parametros!$C$9+Parametros!$B$33-Parametros!$C$13)) -> 3421.4
A22: 5 | B22: =IF($A22+B$16=0,"",Parametros!$C$11+($A22+B$16+1)*Parametros!$C$9+$A22*(Parametros!$B$33-Parametros!$C$13)+B$16*(Parametros!$B$34-Parametros!$C$13)+(Parametros!$C$9+Parametros!$B$33-Parametros!$C$13)) -> 1663.76 | C22: =IF($A22+C$16=0,"",Parametros!$C$11+($A22+C$16+1)*Parametros!$C$9+$A22*(Parametros!$B$33-Parametros!$C$13)+C$16*(Parametros!$B$34-Parametros!$C$13)+(Parametros!$C$9+Parametros!$B$33-Parametros!$C$13)) -> 2168.64 | D22: =IF($A22+D$16=0,"",Parametros!$C$11+($A22+D$16+1)*Parametros!$C$9+$A22*(Parametros!$B$33-Parametros!$C$13)+D$16*(Parametros!$B$34-Parametros!$C$13)+(Parametros!$C$9+Parametros!$B$33-Parametros!$C$13)) -> 2673.52 | E22: =IF($A22+E$16=0,"",Parametros!$C$11+($A22+E$16+1)*Parametros!$C$9+$A22*(Parametros!$B$33-Parametros!$C$13)+E$16*(Parametros!$B$34-Parametros!$C$13)+(Parametros!$C$9+Parametros!$B$33-Parametros!$C$13)) -> 3178.4 | F22: =IF($A22+F$16=0,"",Parametros!$C$11+($A22+F$16+1)*Parametros!$C$9+$A22*(Parametros!$B$33-Parametros!$C$13)+F$16*(Parametros!$B$34-Parametros!$C$13)+(Parametros!$C$9+Parametros!$B$33-Parametros!$C$13)) -> 3683.28
A23: 6 | B23: =IF($A23+B$16=0,"",Parametros!$C$11+($A23+B$16+1)*Parametros!$C$9+$A23*(Parametros!$B$33-Parametros!$C$13)+B$16*(Parametros!$B$34-Parametros!$C$13)+(Parametros!$C$9+Parametros!$B$33-Parametros!$C$13)) -> 1925.64 | C23: =IF($A23+C$16=0,"",Parametros!$C$11+($A23+C$16+1)*Parametros!$C$9+$A23*(Parametros!$B$33-Parametros!$C$13)+C$16*(Parametros!$B$34-Parametros!$C$13)+(Parametros!$C$9+Parametros!$B$33-Parametros!$C$13)) -> 2430.52 | D23: =IF($A23+D$16=0,"",Parametros!$C$11+($A23+D$16+1)*Parametros!$C$9+$A23*(Parametros!$B$33-Parametros!$C$13)+D$16*(Parametros!$B$34-Parametros!$C$13)+(Parametros!$C$9+Parametros!$B$33-Parametros!$C$13)) -> 2935.4 | E23: =IF($A23+E$16=0,"",Parametros!$C$11+($A23+E$16+1)*Parametros!$C$9+$A23*(Parametros!$B$33-Parametros!$C$13)+E$16*(Parametros!$B$34-Parametros!$C$13)+(Parametros!$C$9+Parametros!$B$33-Parametros!$C$13)) -> 3440.28 | F23: =IF($A23+F$16=0,"",Parametros!$C$11+($A23+F$16+1)*Parametros!$C$9+$A23*(Parametros!$B$33-Parametros!$C$13)+F$16*(Parametros!$B$34-Parametros!$C$13)+(Parametros!$C$9+Parametros!$B$33-Parametros!$C$13)) -> 3945.16
A24: 7 | B24: =IF($A24+B$16=0,"",Parametros!$C$11+($A24+B$16+1)*Parametros!$C$9+$A24*(Parametros!$B$33-Parametros!$C$13)+B$16*(Parametros!$B$34-Parametros!$C$13)+(Parametros!$C$9+Parametros!$B$33-Parametros!$C$13)) -> 2187.52 | C24: =IF($A24+C$16=0,"",Parametros!$C$11+($A24+C$16+1)*Parametros!$C$9+$A24*(Parametros!$B$33-Parametros!$C$13)+C$16*(Parametros!$B$34-Parametros!$C$13)+(Parametros!$C$9+Parametros!$B$33-Parametros!$C$13)) -> 2692.4 | D24: =IF($A24+D$16=0,"",Parametros!$C$11+($A24+D$16+1)*Parametros!$C$9+$A24*(Parametros!$B$33-Parametros!$C$13)+D$16*(Parametros!$B$34-Parametros!$C$13)+(Parametros!$C$9+Parametros!$B$33-Parametros!$C$13)) -> 3197.28 | E24: =IF($A24+E$16=0,"",Parametros!$C$11+($A24+E$16+1)*Parametros!$C$9+$A24*(Parametros!$B$33-Parametros!$C$13)+E$16*(Parametros!$B$34-Parametros!$C$13)+(Parametros!$C$9+Parametros!$B$33-Parametros!$C$13)) -> 3702.16 | F24: =IF($A24+F$16=0,"",Parametros!$C$11+($A24+F$16+1)*Parametros!$C$9+$A24*(Parametros!$B$33-Parametros!$C$13)+F$16*(Parametros!$B$34-Parametros!$C$13)+(Parametros!$C$9+Parametros!$B$33-Parametros!$C$13)) -> 4207.04
A26: COM coroa de 513
A27: baias de 270 ↓ / baias de 513 → | B27: 0 | C27: 1 | D27: 2 | E27: 3 | F27: 4
A28: 0 | B28: =IF($A28+B$27=0,"",Parametros!$C$11+($A28+B$27+1)*Parametros!$C$9+$A28*(Parametros!$B$33-Parametros!$C$13)+B$27*(Parametros!$B$34-Parametros!$C$13)+(Parametros!$C$9+Parametros!$B$34-Parametros!$C$13)) | C28: =IF($A28+C$27=0,"",Parametros!$C$11+($A28+C$27+1)*Parametros!$C$9+$A28*(Parametros!$B$33-Parametros!$C$13)+C$27*(Parametros!$B$34-Parametros!$C$13)+(Parametros!$C$9+Parametros!$B$34-Parametros!$C$13)) -> 1102.24 | D28: =IF($A28+D$27=0,"",Parametros!$C$11+($A28+D$27+1)*Parametros!$C$9+$A28*(Parametros!$B$33-Parametros!$C$13)+D$27*(Parametros!$B$34-Parametros!$C$13)+(Parametros!$C$9+Parametros!$B$34-Parametros!$C$13)) -> 1607.12 | E28: =IF($A28+E$27=0,"",Parametros!$C$11+($A28+E$27+1)*Parametros!$C$9+$A28*(Parametros!$B$33-Parametros!$C$13)+E$27*(Parametros!$B$34-Parametros!$C$13)+(Parametros!$C$9+Parametros!$B$34-Parametros!$C$13)) -> 2112 | F28: =IF($A28+F$27=0,"",Parametros!$C$11+($A28+F$27+1)*Parametros!$C$9+$A28*(Parametros!$B$33-Parametros!$C$13)+F$27*(Parametros!$B$34-Parametros!$C$13)+(Parametros!$C$9+Parametros!$B$34-Parametros!$C$13)) -> 2616.88
A29: 1 | B29: =IF($A29+B$27=0,"",Parametros!$C$11+($A29+B$27+1)*Parametros!$C$9+$A29*(Parametros!$B$33-Parametros!$C$13)+B$27*(Parametros!$B$34-Parametros!$C$13)+(Parametros!$C$9+Parametros!$B$34-Parametros!$C$13)) -> 859.24 | C29: =IF($A29+C$27=0,"",Parametros!$C$11+($A29+C$27+1)*Parametros!$C$9+$A29*(Parametros!$B$33-Parametros!$C$13)+C$27*(Parametros!$B$34-Parametros!$C$13)+(Parametros!$C$9+Parametros!$B$34-Parametros!$C$13)) -> 1364.12 | D29: =IF($A29+D$27=0,"",Parametros!$C$11+($A29+D$27+1)*Parametros!$C$9+$A29*(Parametros!$B$33-Parametros!$C$13)+D$27*(Parametros!$B$34-Parametros!$C$13)+(Parametros!$C$9+Parametros!$B$34-Parametros!$C$13)) -> 1869 | E29: =IF($A29+E$27=0,"",Parametros!$C$11+($A29+E$27+1)*Parametros!$C$9+$A29*(Parametros!$B$33-Parametros!$C$13)+E$27*(Parametros!$B$34-Parametros!$C$13)+(Parametros!$C$9+Parametros!$B$34-Parametros!$C$13)) -> 2373.88 | F29: =IF($A29+F$27=0,"",Parametros!$C$11+($A29+F$27+1)*Parametros!$C$9+$A29*(Parametros!$B$33-Parametros!$C$13)+F$27*(Parametros!$B$34-Parametros!$C$13)+(Parametros!$C$9+Parametros!$B$34-Parametros!$C$13)) -> 2878.76
A30: 2 | B30: =IF($A30+B$27=0,"",Parametros!$C$11+($A30+B$27+1)*Parametros!$C$9+$A30*(Parametros!$B$33-Parametros!$C$13)+B$27*(Parametros!$B$34-Parametros!$C$13)+(Parametros!$C$9+Parametros!$B$34-Parametros!$C$13)) -> 1121.12 | C30: =IF($A30+C$27=0,"",Parametros!$C$11+($A30+C$27+1)*Parametros!$C$9+$A30*(Parametros!$B$33-Parametros!$C$13)+C$27*(Parametros!$B$34-Parametros!$C$13)+(Parametros!$C$9+Parametros!$B$34-Parametros!$C$13)) -> 1626 | D30: =IF($A30+D$27=0,"",Parametros!$C$11+($A30+D$27+1)*Parametros!$C$9+$A30*(Parametros!$B$33-Parametros!$C$13)+D$27*(Parametros!$B$34-Parametros!$C$13)+(Parametros!$C$9+Parametros!$B$34-Parametros!$C$13)) -> 2130.88 | E30: =IF($A30+E$27=0,"",Parametros!$C$11+($A30+E$27+1)*Parametros!$C$9+$A30*(Parametros!$B$33-Parametros!$C$13)+E$27*(Parametros!$B$34-Parametros!$C$13)+(Parametros!$C$9+Parametros!$B$34-Parametros!$C$13)) -> 2635.76 | F30: =IF($A30+F$27=0,"",Parametros!$C$11+($A30+F$27+1)*Parametros!$C$9+$A30*(Parametros!$B$33-Parametros!$C$13)+F$27*(Parametros!$B$34-Parametros!$C$13)+(Parametros!$C$9+Parametros!$B$34-Parametros!$C$13)) -> 3140.64
A31: 3 | B31: =IF($A31+B$27=0,"",Parametros!$C$11+($A31+B$27+1)*Parametros!$C$9+$A31*(Parametros!$B$33-Parametros!$C$13)+B$27*(Parametros!$B$34-Parametros!$C$13)+(Parametros!$C$9+Parametros!$B$34-Parametros!$C$13)) -> 1383 | C31: =IF($A31+C$27=0,"",Parametros!$C$11+($A31+C$27+1)*Parametros!$C$9+$A31*(Parametros!$B$33-Parametros!$C$13)+C$27*(Parametros!$B$34-Parametros!$C$13)+(Parametros!$C$9+Parametros!$B$34-Parametros!$C$13)) -> 1887.88 | D31: =IF($A31+D$27=0,"",Parametros!$C$11+($A31+D$27+1)*Parametros!$C$9+$A31*(Parametros!$B$33-Parametros!$C$13)+D$27*(Parametros!$B$34-Parametros!$C$13)+(Parametros!$C$9+Parametros!$B$34-Parametros!$C$13)) -> 2392.76 | E31: =IF($A31+E$27=0,"",Parametros!$C$11+($A31+E$27+1)*Parametros!$C$9+$A31*(Parametros!$B$33-Parametros!$C$13)+E$27*(Parametros!$B$34-Parametros!$C$13)+(Parametros!$C$9+Parametros!$B$34-Parametros!$C$13)) -> 2897.64 | F31: =IF($A31+F$27=0,"",Parametros!$C$11+($A31+F$27+1)*Parametros!$C$9+$A31*(Parametros!$B$33-Parametros!$C$13)+F$27*(Parametros!$B$34-Parametros!$C$13)+(Parametros!$C$9+Parametros!$B$34-Parametros!$C$13)) -> 3402.52
A32: 4 | B32: =IF($A32+B$27=0,"",Parametros!$C$11+($A32+B$27+1)*Parametros!$C$9+$A32*(Parametros!$B$33-Parametros!$C$13)+B$27*(Parametros!$B$34-Parametros!$C$13)+(Parametros!$C$9+Parametros!$B$34-Parametros!$C$13)) -> 1644.88 | C32: =IF($A32+C$27=0,"",Parametros!$C$11+($A32+C$27+1)*Parametros!$C$9+$A32*(Parametros!$B$33-Parametros!$C$13)+C$27*(Parametros!$B$34-Parametros!$C$13)+(Parametros!$C$9+Parametros!$B$34-Parametros!$C$13)) -> 2149.76 | D32: =IF($A32+D$27=0,"",Parametros!$C$11+($A32+D$27+1)*Parametros!$C$9+$A32*(Parametros!$B$33-Parametros!$C$13)+D$27*(Parametros!$B$34-Parametros!$C$13)+(Parametros!$C$9+Parametros!$B$34-Parametros!$C$13)) -> 2654.64 | E32: =IF($A32+E$27=0,"",Parametros!$C$11+($A32+E$27+1)*Parametros!$C$9+$A32*(Parametros!$B$33-Parametros!$C$13)+E$27*(Parametros!$B$34-Parametros!$C$13)+(Parametros!$C$9+Parametros!$B$34-Parametros!$C$13)) -> 3159.52 | F32: =IF($A32+F$27=0,"",Parametros!$C$11+($A32+F$27+1)*Parametros!$C$9+$A32*(Parametros!$B$33-Parametros!$C$13)+F$27*(Parametros!$B$34-Parametros!$C$13)+(Parametros!$C$9+Parametros!$B$34-Parametros!$C$13)) -> 3664.4
A33: 5 | B33: =IF($A33+B$27=0,"",Parametros!$C$11+($A33+B$27+1)*Parametros!$C$9+$A33*(Parametros!$B$33-Parametros!$C$13)+B$27*(Parametros!$B$34-Parametros!$C$13)+(Parametros!$C$9+Parametros!$B$34-Parametros!$C$13)) -> 1906.76 | C33: =IF($A33+C$27=0,"",Parametros!$C$11+($A33+C$27+1)*Parametros!$C$9+$A33*(Parametros!$B$33-Parametros!$C$13)+C$27*(Parametros!$B$34-Parametros!$C$13)+(Parametros!$C$9+Parametros!$B$34-Parametros!$C$13)) -> 2411.64 | D33: =IF($A33+D$27=0,"",Parametros!$C$11+($A33+D$27+1)*Parametros!$C$9+$A33*(Parametros!$B$33-Parametros!$C$13)+D$27*(Parametros!$B$34-Parametros!$C$13)+(Parametros!$C$9+Parametros!$B$34-Parametros!$C$13)) -> 2916.52 | E33: =IF($A33+E$27=0,"",Parametros!$C$11+($A33+E$27+1)*Parametros!$C$9+$A33*(Parametros!$B$33-Parametros!$C$13)+E$27*(Parametros!$B$34-Parametros!$C$13)+(Parametros!$C$9+Parametros!$B$34-Parametros!$C$13)) -> 3421.4 | F33: =IF($A33+F$27=0,"",Parametros!$C$11+($A33+F$27+1)*Parametros!$C$9+$A33*(Parametros!$B$33-Parametros!$C$13)+F$27*(Parametros!$B$34-Parametros!$C$13)+(Parametros!$C$9+Parametros!$B$34-Parametros!$C$13)) -> 3926.28
A34: 6 | B34: =IF($A34+B$27=0,"",Parametros!$C$11+($A34+B$27+1)*Parametros!$C$9+$A34*(Parametros!$B$33-Parametros!$C$13)+B$27*(Parametros!$B$34-Parametros!$C$13)+(Parametros!$C$9+Parametros!$B$34-Parametros!$C$13)) -> 2168.64 | C34: =IF($A34+C$27=0,"",Parametros!$C$11+($A34+C$27+1)*Parametros!$C$9+$A34*(Parametros!$B$33-Parametros!$C$13)+C$27*(Parametros!$B$34-Parametros!$C$13)+(Parametros!$C$9+Parametros!$B$34-Parametros!$C$13)) -> 2673.52 | D34: =IF($A34+D$27=0,"",Parametros!$C$11+($A34+D$27+1)*Parametros!$C$9+$A34*(Parametros!$B$33-Parametros!$C$13)+D$27*(Parametros!$B$34-Parametros!$C$13)+(Parametros!$C$9+Parametros!$B$34-Parametros!$C$13)) -> 3178.4 | E34: =IF($A34+E$27=0,"",Parametros!$C$11+($A34+E$27+1)*Parametros!$C$9+$A34*(Parametros!$B$33-Parametros!$C$13)+E$27*(Parametros!$B$34-Parametros!$C$13)+(Parametros!$C$9+Parametros!$B$34-Parametros!$C$13)) -> 3683.28 | F34: =IF($A34+F$27=0,"",Parametros!$C$11+($A34+F$27+1)*Parametros!$C$9+$A34*(Parametros!$B$33-Parametros!$C$13)+F$27*(Parametros!$B$34-Parametros!$C$13)+(Parametros!$C$9+Parametros!$B$34-Parametros!$C$13)) -> 4188.16
A35: 7 | B35: =IF($A35+B$27=0,"",Parametros!$C$11+($A35+B$27+1)*Parametros!$C$9+$A35*(Parametros!$B$33-Parametros!$C$13)+B$27*(Parametros!$B$34-Parametros!$C$13)+(Parametros!$C$9+Parametros!$B$34-Parametros!$C$13)) -> 2430.52 | C35: =IF($A35+C$27=0,"",Parametros!$C$11+($A35+C$27+1)*Parametros!$C$9+$A35*(Parametros!$B$33-Parametros!$C$13)+C$27*(Parametros!$B$34-Parametros!$C$13)+(Parametros!$C$9+Parametros!$B$34-Parametros!$C$13)) -> 2935.4 | D35: =IF($A35+D$27=0,"",Parametros!$C$11+($A35+D$27+1)*Parametros!$C$9+$A35*(Parametros!$B$33-Parametros!$C$13)+D$27*(Parametros!$B$34-Parametros!$C$13)+(Parametros!$C$9+Parametros!$B$34-Parametros!$C$13)) -> 3440.28 | E35: =IF($A35+E$27=0,"",Parametros!$C$11+($A35+E$27+1)*Parametros!$C$9+$A35*(Parametros!$B$33-Parametros!$C$13)+E$27*(Parametros!$B$34-Parametros!$C$13)+(Parametros!$C$9+Parametros!$B$34-Parametros!$C$13)) -> 3945.16 | F35: =IF($A35+F$27=0,"",Parametros!$C$11+($A35+F$27+1)*Parametros!$C$9+$A35*(Parametros!$B$33-Parametros!$C$13)+F$27*(Parametros!$B$34-Parametros!$C$13)+(Parametros!$C$9+Parametros!$B$34-Parametros!$C$13)) -> 4450.04
A37: Conferência: 270 × 6 = 1.664 (paredões sul e norte) · 513·513·270·270 = 1.626 (fundo e entrada). Nada acima de 1.700 fica na zona do topo do varejo; a coroa NÃO conta como prateleira.
A38: Cabe na baia: 270 → vão livre de | B38: =Parametros!$B$33-Parametros!$C$13+Parametros!$C$9-Parametros!$C$12 -> 246.88 | C38: mm · 513 → | D38: =Parametros!$B$34-Parametros!$C$13+Parametros!$C$9-Parametros!$C$12 -> 489.88 | E38: mm (produto mais alto que isso não entra)

Sheet Pilha
A1: Calculadora de pilha — altura de cada prateleira
A2: Digite a ripa de cada baia (270 ou 513) de baixo para cima nas células azuis; deixe em branco as que não usar. Face da prateleira = topo do nó + metade do painel.
A4: Baia (de baixo p/ cima) | B4: Ripa (mm) | C4: Prateleira nº | D4: Face da prateleira (mm) | E4: Vão livre acima (mm) | F4: Zona do varejo
A5: 1 | B5: 270 | C5: =IF(OR(B5<>"",A5=1),A5,"") -> 1 | D5: =IF(C5="","",Parametros!$C$11+A5*Parametros!$C$9+0+Parametros!$C$12/2) -> 99.98 | E5: =IF(B5="","",B5-Parametros!$C$13+Parametros!$C$9-Parametros!$C$12) -> 246.88 | F5: =IF(D5="","",IF(D5<=800,"chão",IF(D5<=1400,"mãos",IF(D5<=1700,"olhos","topo")))) -> chão
A6: 2 | B6: 270 | C6: =IF(OR(B6<>"",A6=1),A6,"") -> 2 | D6: =IF(C6="","",Parametros!$C$11+A6*Parametros!$C$9+SUM($B$5:B5)-COUNT($B$5:B5)*Parametros!$C$13+Parametros!$C$12/2) -> 361.86 | E6: =IF(B6="","",B6-Parametros!$C$13+Parametros!$C$9-Parametros!$C$12) -> 246.88 | F6: =IF(D6="","",IF(D6<=800,"chão",IF(D6<=1400,"mãos",IF(D6<=1700,"olhos","topo")))) -> chão
A7: 3 | B7: 270 | C7: =IF(OR(B7<>"",A7=1),A7,"") -> 3 | D7: =IF(C7="","",Parametros!$C$11+A7*Parametros!$C$9+SUM($B$5:B6)-COUNT($B$5:B6)*Parametros!$C$13+Parametros!$C$12/2) -> 623.74 | E7: =IF(B7="","",B7-Parametros!$C$13+Parametros!$C$9-Parametros!$C$12) -> 246.88 | F7: =IF(D7="","",IF(D7<=800,"chão",IF(D7<=1400,"mãos",IF(D7<=1700,"olhos","topo")))) -> chão
A8: 4 | B8: 270 | C8: =IF(OR(B8<>"",A8=1),A8,"") -> 4 | D8: =IF(C8="","",Parametros!$C$11+A8*Parametros!$C$9+SUM($B$5:B7)-COUNT($B$5:B7)*Parametros!$C$13+Parametros!$C$12/2) -> 885.62 | E8: =IF(B8="","",B8-Parametros!$C$13+Parametros!$C$9-Parametros!$C$12) -> 246.88 | F8: =IF(D8="","",IF(D8<=800,"chão",IF(D8<=1400,"mãos",IF(D8<=1700,"olhos","topo")))) -> mãos
A9: 5 | B9: 270 | C9: =IF(OR(B9<>"",A9=1),A9,"") -> 5 | D9: =IF(C9="","",Parametros!$C$11+A9*Parametros!$C$9+SUM($B$5:B8)-COUNT($B$5:B8)*Parametros!$C$13+Parametros!$C$12/2) -> 1147.5 | E9: =IF(B9="","",B9-Parametros!$C$13+Parametros!$C$9-Parametros!$C$12) -> 246.88 | F9: =IF(D9="","",IF(D9<=800,"chão",IF(D9<=1400,"mãos",IF(D9<=1700,"olhos","topo")))) -> mãos
A10: 6 | B10: 270 | C10: =IF(OR(B10<>"",A10=1),A10,"") -> 6 | D10: =IF(C10="","",Parametros!$C$11+A10*Parametros!$C$9+SUM($B$5:B9)-COUNT($B$5:B9)*Parametros!$C$13+Parametros!$C$12/2) -> 1409.38 | E10: =IF(B10="","",B10-Parametros!$C$13+Parametros!$C$9-Parametros!$C$12) -> 246.88 | F10: =IF(D10="","",IF(D10<=800,"chão",IF(D10<=1400,"mãos",IF(D10<=1700,"olhos","topo")))) -> olhos
A11: 7 | C11: =IF(OR(B11<>"",A11=1),A11,"") | D11: =IF(C11="","",Parametros!$C$11+A11*Parametros!$C$9+SUM($B$5:B10)-COUNT($B$5:B10)*Parametros!$C$13+Parametros!$C$12/2) | E11: =IF(B11="","",B11-Parametros!$C$13+Parametros!$C$9-Parametros!$C$12) | F11: =IF(D11="","",IF(D11<=800,"chão",IF(D11<=1400,"mãos",IF(D11<=1700,"olhos","topo"))))
A12: 8 | C12: =IF(OR(B12<>"",A12=1),A12,"") | D12: =IF(C12="","",Parametros!$C$11+A12*Parametros!$C$9+SUM($B$5:B11)-COUNT($B$5:B11)*Parametros!$C$13+Parametros!$C$12/2) | E12: =IF(B12="","",B12-Parametros!$C$13+Parametros!$C$9-Parametros!$C$12) | F12: =IF(D12="","",IF(D12<=800,"chão",IF(D12<=1400,"mãos",IF(D12<=1700,"olhos","topo"))))
A13: topo | C13: =COUNT(B5:B12)+1 -> 7 | D13: =Parametros!$C$11+C13*Parametros!$C$9+SUM(B5:B12)-COUNT(B5:B12)*Parametros!$C$13+Parametros!$C$12/2 -> 1671.26 | F13: =IF(D13<=800,"chão",IF(D13<=1400,"mãos",IF(D13<=1700,"olhos","topo"))) -> olhos
A15: Altura externa do módulo | D15: =Parametros!$C$11+(COUNT(B5:B12)+1)*Parametros!$C$9+SUM(B5:B12)-COUNT(B5:B12)*Parametros!$C$13 -> 1663.76
A16: Prateleiras | D16: =COUNT(B5:B12)+1 -> 7
A17: Razão altura ÷ base (500 mm) | D17: =D15/Profundidade!C7 -> 3.3257906 | E17: : 1 · acima de 3 pede ancoragem na parede
A19: Zonas do varejo: chão até 800 · mãos 800–1.400 · olhos 1.400–1.700 (vende 35–50% mais) · topo acima de 1.700. Exemplo carregado: 270 × 6 = paredão sul, faces 100 · 362 · 624 · 886 · 1.148 · 1.409 · 1.671.

Sheet Paineis
A1: A grade de painéis e a regra da proporção
A2: Das 12 combinações largura × comprimento, ficam as que têm comprimento ÷ largura entre RAZ_MIN e RAZ_MAX. As demais saem para não estocar peça que empena (200 estreito e longo) ou quase quadrado.
A4: Largura ↓ / Comprimento → | B4: 360 | C4: 450 | D4: 634 | E4: 754
A5: 200 | B5: =IF(AND(B$4/$A5>=Parametros!$C$14,B$4/$A5<=Parametros!$C$15),TEXT(B$4/$A5,"0.00")&" ✔","sai · "&TEXT(B$4/$A5,"0.00")) -> 1.80 ✔ | C5: =IF(AND(C$4/$A5>=Parametros!$C$14,C$4/$A5<=Parametros!$C$15),TEXT(C$4/$A5,"0.00")&" ✔","sai · "&TEXT(C$4/$A5,"0.00")) -> 2.25 ✔ | D5: =IF(AND(D$4/$A5>=Parametros!$C$14,D$4/$A5<=Parametros!$C$15),TEXT(D$4/$A5,"0.00")&" ✔","sai · "&TEXT(D$4/$A5,"0.00")) -> sai · 3.17 | E5: =IF(AND(E$4/$A5>=Parametros!$C$14,E$4/$A5<=Parametros!$C$15),TEXT(E$4/$A5,"0.00")&" ✔","sai · "&TEXT(E$4/$A5,"0.00")) -> sai · 3.77
A6: 300 | B6: =IF(AND(B$4/$A6>=Parametros!$C$14,B$4/$A6<=Parametros!$C$15),TEXT(B$4/$A6,"0.00")&" ✔","sai · "&TEXT(B$4/$A6,"0.00")) -> sai · 1.20 | C6: =IF(AND(C$4/$A6>=Parametros!$C$14,C$4/$A6<=Parametros!$C$15),TEXT(C$4/$A6,"0.00")&" ✔","sai · "&TEXT(C$4/$A6,"0.00")) -> 1.50 ✔ | D6: =IF(AND(D$4/$A6>=Parametros!$C$14,D$4/$A6<=Parametros!$C$15),TEXT(D$4/$A6,"0.00")&" ✔","sai · "&TEXT(D$4/$A6,"0.00")) -> 2.11 ✔ | E6: =IF(AND(E$4/$A6>=Parametros!$C$14,E$4/$A6<=Parametros!$C$15),TEXT(E$4/$A6,"0.00")&" ✔","sai · "&TEXT(E$4/$A6,"0.00")) -> 2.51 ✔
A7: 460 | B7: =IF(AND(B$4/$A7>=Parametros!$C$14,B$4/$A7<=Parametros!$C$15),TEXT(B$4/$A7,"0.00")&" ✔","sai · "&TEXT(B$4/$A7,"0.00")) -> sai · 0.78 | C7: =IF(AND(C$4/$A7>=Parametros!$C$14,C$4/$A7<=Parametros!$C$15),TEXT(C$4/$A7,"0.00")&" ✔","sai · "&TEXT(C$4/$A7,"0.00")) -> sai · 0.98 | D7: =IF(AND(D$4/$A7>=Parametros!$C$14,D$4/$A7<=Parametros!$C$15),TEXT(D$4/$A7,"0.00")&" ✔","sai · "&TEXT(D$4/$A7,"0.00")) -> 1.38 ✔ | E7: =IF(AND(E$4/$A7>=Parametros!$C$14,E$4/$A7<=Parametros!$C$15),TEXT(E$4/$A7,"0.00")&" ✔","sai · "&TEXT(E$4/$A7,"0.00")) -> 1.64 ✔
A9: Painéis que ficam (7): | B9: =SUMPRODUCT(--(RIGHT(B5:E7,1)="✔")) -> 7
A10: Os sete: 200×360 · 200×450 · 300×450 · 300×634 · 300×754 · 460×634 · 460×754. Saem: 200×634 e 200×754 (empenam), 300×360, 460×360 e 460×450 (quase quadrados).

Sheet Modulos
A1: Todas as combinações de painel × número de vãos
A2: Um módulo = uma ripa de largura (profundidade) + uma ripa de comprimento (vão) × N vãos + uma pilha de baias (altura). Aqui variam painel e N; a altura vem da aba Altura ou da calculadora Pilha.
A4: Nº de prateleiras para a contagem de peças → | E4: 7 | F4: (baias + 1; o exemplo é a pilha 270 × 6)
A6: Painel | B6: Largura (ripa) | C6: Comprimento (ripa) | D6: N vãos | E6: Comprimento externo | F6: Profundidade externa | G6: Área de piso (m²) | H6: Frente por prateleira (m) | I6: Trizetas | J6: Cruzetas | K6: Peças L (coroa) | L6: Tampas | M6: Painéis | N6: Ripas de comprimento | O6: Ripas de largura | P6: Ripas verticais
A7: 200×360 | B7: =Parametros!$B$20 -> 200 | C7: =Parametros!$B$26 -> 315 | D7: 1 | E7: =2*Parametros!$C$6+(D7-1)*Parametros!$C$7+D7*(C7-Parametros!$C$13) -> 357.02 | F7: =B7+2*(Parametros!$C$8-Parametros!$C$5) -> 285.26 | G7: =E7*F7/1000000 -> 0.10184353 | H7: =E7/1000 -> 0.35702 | I7: =4*$E$4 -> 28 | J7: =2*(D7-1)*$E$4 -> 0 | K7: 0 | L7: =2*(D7+1) -> 4 | M7: =D7*$E$4 -> 7 | N7: =2*D7*$E$4 -> 14 | O7: =(D7+1)*$E$4 -> 14 | P7: =2*(D7+1)*($E$4-1) -> 24
A8: 200×360 | B8: =Parametros!$B$20 -> 200 | C8: =Parametros!$B$26 -> 315 | D8: 2 | E8: =2*Parametros!$C$6+(D8-1)*Parametros!$C$7+D8*(C8-Parametros!$C$13) -> 692.12 | F8: =B8+2*(Parametros!$C$8-Parametros!$C$5) -> 285.26 | G8: =E8*F8/1000000 -> 0.19743415 | H8: =E8/1000 -> 0.69212 | I8: =4*$E$4 -> 28 | J8: =2*(D8-1)*$E$4 -> 14 | K8: 0 | L8: =2*(D8+1) -> 6 | M8: =D8*$E$4 -> 14 | N8: =2*D8*$E$4 -> 28 | O8: =(D8+1)*$E$4 -> 21 | P8: =2*(D8+1)*($E$4-1) -> 36
A9: 200×360 | B9: =Parametros!$B$20 -> 200 | C9: =Parametros!$B$26 -> 315 | D9: 3 | E9: =2*Parametros!$C$6+(D9-1)*Parametros!$C$7+D9*(C9-Parametros!$C$13) -> 1027.22 | F9: =B9+2*(Parametros!$C$8-Parametros!$C$5) -> 285.26 | G9: =E9*F9/1000000 -> 0.29302478 | H9: =E9/1000 -> 1.02722 | I9: =4*$E$4 -> 28 | J9: =2*(D9-1)*$E$4 -> 28 | K9: 0 | L9: =2*(D9+1) -> 8 | M9: =D9*$E$4 -> 21 | N9: =2*D9*$E$4 -> 42 | O9: =(D9+1)*$E$4 -> 28 | P9: =2*(D9+1)*($E$4-1) -> 48
A10: 200×360 | B10: =Parametros!$B$20 -> 200 | C10: =Parametros!$B$26 -> 315 | D10: 4 | E10: =2*Parametros!$C$6+(D10-1)*Parametros!$C$7+D10*(C10-Parametros!$C$13) -> 1362.32 | F10: =B10+2*(Parametros!$C$8-Parametros!$C$5) -> 285.26 | G10: =E10*F10/1000000 -> 0.3886154 | H10: =E10/1000 -> 1.36232 | I10: =4*$E$4 -> 28 | J10: =2*(D10-1)*$E$4 -> 42 | K10: 0 | L10: =2*(D10+1) -> 10 | M10: =D10*$E$4 -> 28 | N10: =2*D10*$E$4 -> 56 | O10: =(D10+1)*$E$4 -> 35 | P10: =2*(D10+1)*($E$4-1) -> 60
A11: 200×360 | B11: =Parametros!$B$20 -> 200 | C11: =Parametros!$B$26 -> 315 | D11: 5 | E11: =2*Parametros!$C$6+(D11-1)*Parametros!$C$7+D11*(C11-Parametros!$C$13) -> 1697.42 | F11: =B11+2*(Parametros!$C$8-Parametros!$C$5) -> 285.26 | G11: =E11*F11/1000000 -> 0.48420603 | H11: =E11/1000 -> 1.69742 | I11: =4*$E$4 -> 28 | J11: =2*(D11-1)*$E$4 -> 56 | K11: 0 | L11: =2*(D11+1) -> 12 | M11: =D11*$E$4 -> 35 | N11: =2*D11*$E$4 -> 70 | O11: =(D11+1)*$E$4 -> 42 | P11: =2*(D11+1)*($E$4-1) -> 72
A12: 200×360 | B12: =Parametros!$B$20 -> 200 | C12: =Parametros!$B$26 -> 315 | D12: 6 | E12: =2*Parametros!$C$6+(D12-1)*Parametros!$C$7+D12*(C12-Parametros!$C$13) -> 2032.52 | F12: =B12+2*(Parametros!$C$8-Parametros!$C$5) -> 285.26 | G12: =E12*F12/1000000 -> 0.57979666 | H12: =E12/1000 -> 2.03252 | I12: =4*$E$4 -> 28 | J12: =2*(D12-1)*$E$4 -> 70 | K12: 0 | L12: =2*(D12+1) -> 14 | M12: =D12*$E$4 -> 42 | N12: =2*D12*$E$4 -> 84 | O12: =(D12+1)*$E$4 -> 49 | P12: =2*(D12+1)*($E$4-1) -> 84
A13: 200×360 | B13: =Parametros!$B$20 -> 200 | C13: =Parametros!$B$26 -> 315 | D13: 7 | E13: =2*Parametros!$C$6+(D13-1)*Parametros!$C$7+D13*(C13-Parametros!$C$13) -> 2367.62 | F13: =B13+2*(Parametros!$C$8-Parametros!$C$5) -> 285.26 | G13: =E13*F13/1000000 -> 0.67538728 | H13: =E13/1000 -> 2.36762 | I13: =4*$E$4 -> 28 | J13: =2*(D13-1)*$E$4 -> 84 | K13: 0 | L13: =2*(D13+1) -> 16 | M13: =D13*$E$4 -> 49 | N13: =2*D13*$E$4 -> 98 | O13: =(D13+1)*$E$4 -> 56 | P13: =2*(D13+1)*($E$4-1) -> 96
A14: 200×360 | B14: =Parametros!$B$20 -> 200 | C14: =Parametros!$B$26 -> 315 | D14: 8 | E14: =2*Parametros!$C$6+(D14-1)*Parametros!$C$7+D14*(C14-Parametros!$C$13) -> 2702.72 | F14: =B14+2*(Parametros!$C$8-Parametros!$C$5) -> 285.26 | G14: =E14*F14/1000000 -> 0.77097791 | H14: =E14/1000 -> 2.70272 | I14: =4*$E$4 -> 28 | J14: =2*(D14-1)*$E$4 -> 98 | K14: 0 | L14: =2*(D14+1) -> 18 | M14: =D14*$E$4 -> 56 | N14: =2*D14*$E$4 -> 112 | O14: =(D14+1)*$E$4 -> 63 | P14: =2*(D14+1)*($E$4-1) -> 108
A15: 200×360 | B15: =Parametros!$B$20 -> 200 | C15: =Parametros!$B$26 -> 315 | D15: 9 | E15: =2*Parametros!$C$6+(D15-1)*Parametros!$C$7+D15*(C15-Parametros!$C$13) -> 3037.82 | F15: =B15+2*(Parametros!$C$8-Parametros!$C$5) -> 285.26 | G15: =E15*F15/1000000 -> 0.86656853 | H15: =E15/1000 -> 3.03782 | I15: =4*$E$4 -> 28 | J15: =2*(D15-1)*$E$4 -> 112 | K15: 0 | L15: =2*(D15+1) -> 20 | M15: =D15*$E$4 -> 63 | N15: =2*D15*$E$4 -> 126 | O15: =(D15+1)*$E$4 -> 70 | P15: =2*(D15+1)*($E$4-1) -> 120
A16: 200×360 | B16: =Parametros!$B$20 -> 200 | C16: =Parametros!$B$26 -> 315 | D16: 10 | E16: =2*Parametros!$C$6+(D16-1)*Parametros!$C$7+D16*(C16-Parametros!$C$13) -> 3372.92 | F16: =B16+2*(Parametros!$C$8-Parametros!$C$5) -> 285.26 | G16: =E16*F16/1000000 -> 0.96215916 | H16: =E16/1000 -> 3.37292 | I16: =4*$E$4 -> 28 | J16: =2*(D16-1)*$E$4 -> 126 | K16: 0 | L16: =2*(D16+1) -> 22 | M16: =D16*$E$4 -> 70 | N16: =2*D16*$E$4 -> 140 | O16: =(D16+1)*$E$4 -> 77 | P16: =2*(D16+1)*($E$4-1) -> 132
A17: 200×360 | B17: =Parametros!$B$20 -> 200 | C17: =Parametros!$B$26 -> 315 | D17: 11 | E17: =2*Parametros!$C$6+(D17-1)*Parametros!$C$7+D17*(C17-Parametros!$C$13) -> 3708.02 | F17: =B17+2*(Parametros!$C$8-Parametros!$C$5) -> 285.26 | G17: =E17*F17/1000000 -> 1.0577498 | H17: =E17/1000 -> 3.70802 | I17: =4*$E$4 -> 28 | J17: =2*(D17-1)*$E$4 -> 140 | K17: 0 | L17: =2*(D17+1) -> 24 | M17: =D17*$E$4 -> 77 | N17: =2*D17*$E$4 -> 154 | O17: =(D17+1)*$E$4 -> 84 | P17: =2*(D17+1)*($E$4-1) -> 144
A18: 200×360 | B18: =Parametros!$B$20 -> 200 | C18: =Parametros!$B$26 -> 315 | D18: 12 | E18: =2*Parametros!$C$6+(D18-1)*Parametros!$C$7+D18*(C18-Parametros!$C$13) -> 4043.12 | F18: =B18+2*(Parametros!$C$8-Parametros!$C$5) -> 285.26 | G18: =E18*F18/1000000 -> 1.1533404 | H18: =E18/1000 -> 4.04312 | I18: =4*$E$4 -> 28 | J18: =2*(D18-1)*$E$4 -> 154 | K18: 0 | L18: =2*(D18+1) -> 26 | M18: =D18*$E$4 -> 84 | N18: =2*D18*$E$4 -> 168 | O18: =(D18+1)*$E$4 -> 91 | P18: =2*(D18+1)*($E$4-1) -> 156
... A24: 200×360 | B24: =Parametros!$B$20 -> 200 | C24: =Parametros!$B$26 -> 315 | D24: 18 | E24: =2*Parametros!$C$6+(D24-1)*Parametros!$C$7+D24*(C24-Parametros!$C$13) -> 6053.72 | F24: =B24+2*(Parametros!$C$8-Parametros!$C$5) -> 285.26 | G24: =E24*F24/1000000 -> 1.7268842 | H24: =E24/1000 -> 6.05372 | I24: =4*$E$4 -> 28 | J24: =2*(D24-1)*$E$4 -> 238 | K24: 0 | L24: =2*(D24+1) -> 38 | M24: =D24*$E$4 -> 126 | N24: =2*D24*$E$4 -> 252 | O24: =(D24+1)*$E$4 -> 133 | P24: =2*(D24+1)*($E$4-1) -> 228
A25: 200×450 | B25: =Parametros!$B$20 -> 200 | C25: =Parametros!$B$27 -> 415 | D25: 1 | E25: =2*Parametros!$C$6+(D25-1)*Parametros!$C$7+D25*(C25-Parametros!$C$13) -> 457.02 | F25: =B25+2*(Parametros!$C$8-Parametros!$C$5) -> 285.26 | G25: =E25*F25/1000000 -> 0.13036953 | H25: =E25/1000 -> 0.45702 | I25: =4*$E$4 -> 28 | J25: =2*(D25-1)*$E$4 -> 0 | K25: 0 | L25: =2*(D25+1) -> 4 | M25: =D25*$E$4 -> 7 | N25: =2*D25*$E$4 -> 14 | O25: =(D25+1)*$E$4 -> 14 | P25: =2*(D25+1)*($E$4-1) -> 24
A26: 200×450 | B26: =Parametros!$B$20 -> 200 | C26: =Parametros!$B$27 -> 415 | D26: 2 | E26: =2*Parametros!$C$6+(D26-1)*Parametros!$C$7+D26*(C26-Parametros!$C$13) -> 892.12 | F26: =B26+2*(Parametros!$C$8-Parametros!$C$5) -> 285.26 | G26: =E26*F26/1000000 -> 0.25448615 | H26: =E26/1000 -> 0.89212 | I26: =4*$E$4 -> 28 | J26: =2*(D26-1)*$E$4 -> 14 | K26: 0 | L26: =2*(D26+1) -> 6 | M26: =D26*$E$4 -> 14 | N26: =2*D26*$E$4 -> 28 | O26: =(D26+1)*$E$4 -> 21 | P26: =2*(D26+1)*($E$4-1) -> 36
A27: 200×450 | B27: =Parametros!$B$20 -> 200 | C27: =Parametros!$B$27 -> 415 | D27: 3 | E27: =2*Parametros!$C$6+(D27-1)*Parametros!$C$7+D27*(C27-Parametros!$C$13) -> 1327.22 | F27: =B27+2*(Parametros!$C$8-Parametros!$C$5) -> 285.26 | G27: =E27*F27/1000000 -> 0.37860278 | H27: =E27/1000 -> 1.32722 | I27: =4*$E$4 -> 28 | J27: =2*(D27-1)*$E$4 -> 28 | K27: 0 | L27: =2*(D27+1) -> 8 | M27: =D27*$E$4 -> 21 | N27: =2*D27*$E$4 -> 42 | O27: =(D27+1)*$E$4 -> 28 | P27: =2*(D27+1)*($E$4-1) -> 48
A28: 200×450 | B28: =Parametros!$B$20 -> 200 | C28: =Parametros!$B$27 -> 415 | D28: 4 | E28: =2*Parametros!$C$6+(D28-1)*Parametros!$C$7+D28*(C28-Parametros!$C$13) -> 1762.32 | F28: =B28+2*(Parametros!$C$8-Parametros!$C$5) -> 285.26 | G28: =E28*F28/1000000 -> 0.5027194 | H28: =E28/1000 -> 1.76232 | I28: =4*$E$4 -> 28 | J28: =2*(D28-1)*$E$4 -> 42 | K28: 0 | L28: =2*(D28+1) -> 10 | M28: =D28*$E$4 -> 28 | N28: =2*D28*$E$4 -> 56 | O28: =(D28+1)*$E$4 -> 35 | P28: =2*(D28+1)*($E$4-1) -> 60
A29: 200×450 | B29: =Parametros!$B$20 -> 200 | C29: =Parametros!$B$27 -> 415 | D29: 5 | E29: =2*Parametros!$C$6+(D29-1)*Parametros!$C$7+D29*(C29-Parametros!$C$13) -> 2197.42 | F29: =B29+2*(Parametros!$C$8-Parametros!$C$5) -> 285.26 | G29: =E29*F29/1000000 -> 0.62683603 | H29: =E29/1000 -> 2.19742 | I29: =4*$E$4 -> 28 | J29: =2*(D29-1)*$E$4 -> 56 | K29: 0 | L29: =2*(D29+1) -> 12 | M29: =D29*$E$4 -> 35 | N29: =2*D29*$E$4 -> 70 | O29: =(D29+1)*$E$4 -> 42 | P29: =2*(D29+1)*($E$4-1) -> 72
A30: 200×450 | B30: =Parametros!$B$20 -> 200 | C30: =Parametros!$B$27 -> 415 | D30: 6 | E30: =2*Parametros!$C$6+(D30-1)*Parametros!$C$7+D30*(C30-Parametros!$C$13) -> 2632.52 | F30: =B30+2*(Parametros!$C$8-Parametros!$C$5) -> 285.26 | G30: =E30*F30/1000000 -> 0.75095266 | H30: =E30/1000 -> 2.63252 | I30: =4*$E$4 -> 28 | J30: =2*(D30-1)*$E$4 -> 70 | K30: 0 | L30: =2*(D30+1) -> 14 | M30: =D30*$E$4 -> 42 | N30: =2*D30*$E$4 -> 84 | O30: =(D30+1)*$E$4 -> 49 | P30: =2*(D30+1)*($E$4-1) -> 84
A31: 200×450 | B31: =Parametros!$B$20 -> 200 | C31: =Parametros!$B$27 -> 415 | D31: 7 | E31: =2*Parametros!$C$6+(D31-1)*Parametros!$C$7+D31*(C31-Parametros!$C$13) -> 3067.62 | F31: =B31+2*(Parametros!$C$8-Parametros!$C$5) -> 285.26 | G31: =E31*F31/1000000 -> 0.87506928 | H31: =E31/1000 -> 3.06762 | I31: =4*$E$4 -> 28 | J31: =2*(D31-1)*$E$4 -> 84 | K31: 0 | L31: =2*(D31+1) -> 16 | M31: =D31*$E$4 -> 49 | N31: =2*D31*$E$4 -> 98 | O31: =(D31+1)*$E$4 -> 56 | P31: =2*(D31+1)*($E$4-1) -> 96
A32: 200×450 | B32: =Parametros!$B$20 -> 200 | C32: =Parametros!$B$27 -> 415 | D32: 8 | E32: =2*Parametros!$C$6+(D32-1)*Parametros!$C$7+D32*(C32-Parametros!$C$13) -> 3502.72 | F32: =B32+2*(Parametros!$C$8-Parametros!$C$5) -> 285.26 | G32: =E32*F32/1000000 -> 0.99918591 | H32: =E32/1000 -> 3.50272 | I32: =4*$E$4 -> 28 | J32: =2*(D32-1)*$E$4 -> 98 | K32: 0 | L32: =2*(D32+1) -> 18 | M32: =D32*$E$4 -> 56 | N32: =2*D32*$E$4 -> 112 | O32: =(D32+1)*$E$4 -> 63 | P32: =2*(D32+1)*($E$4-1) -> 108
A33: 200×450 | B33: =Parametros!$B$20 -> 200 | C33: =Parametros!$B$27 -> 415 | D33: 9 | E33: =2*Parametros!$C$6+(D33-1)*Parametros!$C$7+D33*(C33-Parametros!$C$13) -> 3937.82 | F33: =B33+2*(Parametros!$C$8-Parametros!$C$5) -> 285.26 | G33: =E33*F33/1000000 -> 1.1233025 | H33: =E33/1000 -> 3.93782 | I33: =4*$E$4 -> 28 | J33: =2*(D33-1)*$E$4 -> 112 | K33: 0 | L33: =2*(D33+1) -> 20 | M33: =D33*$E$4 -> 63 | N33: =2*D33*$E$4 -> 126 | O33: =(D33+1)*$E$4 -> 70 | P33: =2*(D33+1)*($E$4-1) -> 120
A34: 200×450 | B34: =Parametros!$B$20 -> 200 | C34: =Parametros!$B$27 -> 415 | D34: 10 | E34: =2*Parametros!$C$6+(D34-1)*Parametros!$C$7+D34*(C34-Parametros!$C$13) -> 4372.92 | F34: =B34+2*(Parametros!$C$8-Parametros!$C$5) -> 285.26 | G34: =E34*F34/1000000 -> 1.2474192 | H34: =E34/1000 -> 4.37292 | I34: =4*$E$4 -> 28 | J34: =2*(D34-1)*$E$4 -> 126 | K34: 0 | L34: =2*(D34+1) -> 22 | M34: =D34*$E$4 -> 70 | N34: =2*D34*$E$4 -> 140 | O34: =(D34+1)*$E$4 -> 77 | P34: =2*(D34+1)*($E$4-1) -> 132
A35: 200×450 | B35: =Parametros!$B$20 -> 200 | C35: =Parametros!$B$27 -> 415 | D35: 11 | E35: =2*Parametros!$C$6+(D35-1)*Parametros!$C$7+D35*(C35-Parametros!$C$13) -> 4808.02 | F35: =B35+2*(Parametros!$C$8-Parametros!$C$5) -> 285.26 | G35: =E35*F35/1000000 -> 1.3715358 | H35: =E35/1000 -> 4.80802 | I35: =4*$E$4 -> 28 | J35: =2*(D35-1)*$E$4 -> 140 | K35: 0 | L35: =2*(D35+1) -> 24 | M35: =D35*$E$4 -> 77 | N35: =2*D35*$E$4 -> 154 | O35: =(D35+1)*$E$4 -> 84 | P35: =2*(D35+1)*($E$4-1) -> 144
A36: 200×450 | B36: =Parametros!$B$20 -> 200 | C36: =Parametros!$B$27 -> 415 | D36: 12 | E36: =2*Parametros!$C$6+(D36-1)*Parametros!$C$7+D36*(C36-Parametros!$C$13) -> 5243.12 | F36: =B36+2*(Parametros!$C$8-Parametros!$C$5) -> 285.26 | G36: =E36*F36/1000000 -> 1.4956524 | H36: =E36/1000 -> 5.24312 | I36: =4*$E$4 -> 28 | J36: =2*(D36-1)*$E$4 -> 154 | K36: 0 | L36: =2*(D36+1) -> 26 | M36: =D36*$E$4 -> 84 | N36: =2*D36*$E$4 -> 168 | O36: =(D36+1)*$E$4 -> 91 | P36: =2*(D36+1)*($E$4-1) -> 156
... A42: 200×450 | B42: =Parametros!$B$20 -> 200 | C42: =Parametros!$B$27 -> 415 | D42: 18 | E42: =2*Parametros!$C$6+(D42-1)*Parametros!$C$7+D42*(C42-Parametros!$C$13) -> 7853.72 | F42: =B42+2*(Parametros!$C$8-Parametros!$C$5) -> 285.26 | G42: =E42*F42/1000000 -> 2.2403522 | H42: =E42/1000 -> 7.85372 | I42: =4*$E$4 -> 28 | J42: =2*(D42-1)*$E$4 -> 238 | K42: 0 | L42: =2*(D42+1) -> 38 | M42: =D42*$E$4 -> 126 | N42: =2*D42*$E$4 -> 252 | O42: =(D42+1)*$E$4 -> 133 | P42: =2*(D42+1)*($E$4-1) -> 228
A43: 300×450 | B43: =Parametros!$B$21 -> 287 | C43: =Parametros!$B$27 -> 415 | D43: 1 | E43: =2*Parametros!$C$6+(D43-1)*Parametros!$C$7+D43*(C43-Parametros!$C$13) -> 457.02 | F43: =B43+2*(Parametros!$C$8-Parametros!$C$5) -> 372.26 | G43: =E43*F43/1000000 -> 0.17013027 | H43: =E43/1000 -> 0.45702 | I43: =4*$E$4 -> 28 | J43: =2*(D43-1)*$E$4 -> 0 | K43: 0 | L43: =2*(D43+1) -> 4 | M43: =D43*$E$4 -> 7 | N43: =2*D43*$E$4 -> 14 | O43: =(D43+1)*$E$4 -> 14 | P43: =2*(D43+1)*($E$4-1) -> 24
A44: 300×450 | B44: =Parametros!$B$21 -> 287 | C44: =Parametros!$B$27 -> 415 | D44: 2 | E44: =2*Parametros!$C$6+(D44-1)*Parametros!$C$7+D44*(C44-Parametros!$C$13) -> 892.12 | F44: =B44+2*(Parametros!$C$8-Parametros!$C$5) -> 372.26 | G44: =E44*F44/1000000 -> 0.33210059 | H44: =E44/1000 -> 0.89212 | I44: =4*$E$4 -> 28 | J44: =2*(D44-1)*$E$4 -> 14 | K44: 0 | L44: =2*(D44+1) -> 6 | M44: =D44*$E$4 -> 14 | N44: =2*D44*$E$4 -> 28 | O44: =(D44+1)*$E$4 -> 21 | P44: =2*(D44+1)*($E$4-1) -> 36
A45: 300×450 | B45: =Parametros!$B$21 -> 287 | C45: =Parametros!$B$27 -> 415 | D45: 3 | E45: =2*Parametros!$C$6+(D45-1)*Parametros!$C$7+D45*(C45-Parametros!$C$13) -> 1327.22 | F45: =B45+2*(Parametros!$C$8-Parametros!$C$5) -> 372.26 | G45: =E45*F45/1000000 -> 0.49407092 | H45: =E45/1000 -> 1.32722 | I45: =4*$E$4 -> 28 | J45: =2*(D45-1)*$E$4 -> 28 | K45: 0 | L45: =2*(D45+1) -> 8 | M45: =D45*$E$4 -> 21 | N45: =2*D45*$E$4 -> 42 | O45: =(D45+1)*$E$4 -> 28 | P45: =2*(D45+1)*($E$4-1) -> 48
A46: 300×450 | B46: =Parametros!$B$21 -> 287 | C46: =Parametros!$B$27 -> 415 | D46: 4 | E46: =2*Parametros!$C$6+(D46-1)*Parametros!$C$7+D46*(C46-Parametros!$C$13) -> 1762.32 | F46: =B46+2*(Parametros!$C$8-Parametros!$C$5) -> 372.26 | G46: =E46*F46/1000000 -> 0.65604124 | H46: =E46/1000 -> 1.76232 | I46: =4*$E$4 -> 28 | J46: =2*(D46-1)*$E$4 -> 42 | K46: 0 | L46: =2*(D46+1) -> 10 | M46: =D46*$E$4 -> 28 | N46: =2*D46*$E$4 -> 56 | O46: =(D46+1)*$E$4 -> 35 | P46: =2*(D46+1)*($E$4-1) -> 60
