Workbook

Sheet Kit
A1: Nitron Mob PDV — kit flexível
A2: 13 peças: 3 painéis, 6 ripas (todas PI existentes), 4 conectores. Custo unitário em amarelo é entrada; a madeira usa R$ 19.03/kg do caderno.
A4: Peça | B4: Código | C4: Medida (mm) | D4: Massa unit. (kg) | E4: Custo unit. (R$) | F4: Papel
A5: Painel 300×450 | B5: novo · pinus 15 | C5: 300 × 450 | D5: 1.1259 | E5: 21.4259 | F5: prateleira rasa curta — ponta, canto, caixa–pilar
A6: Painel 300×754 | B6: novo · pinus 15 | C6: 300 × 754 | D6: 1.8865 | E6: 35.9002 | F6: prateleira rasa padrão — 82% dos SKUs cabem
A7: Painel 460×754 | B7: novo · pinus 15 | C7: 460 × 754 | D7: 2.8926 | E7: 55.047 | F7: prateleira funda — lixeira, cesto, caixa grande, e a parede mais estável
A8: Ripa largura 287 | B8: BLA-03-AC | C8: 287 | D8: 0.0649 | E8: 1.2359 | F8: profundidade 372
A9: Ripa largura 415 | B9: PSC-02 | C9: 415 | D9: 0.0939 | E9: 1.787 | F9: profundidade 500 (a mesma PI serve de vão 450)
A10: Ripa comprimento 415 | B10: PSC-02 | C10: 415 | D10: 0.0939 | E10: 1.787 | F10: vão de 450
A11: Ripa comprimento 717 | B11: PSC-04 | C11: 717 | D11: 0.1622 | E11: 3.0875 | F11: vão de 754
A12: Ripa vertical 270 | B12: BAL-02-AC | C12: 270 | D12: 0.0611 | E12: 1.1626 | F12: baia de 247 livres
A13: Ripa vertical 513 | B13: PSA-05 | C13: 513 | D13: 0.1161 | E13: 2.209 | F13: baia de 490 livres — e a coroa da arara
A14: Pé | B14: sobra de ripa | C14: 60 | D14: 0.0136 | E14: 0.2584
A15: Trizeta | B15: PP · molde existe | C15: — | D15: 0.0443 | E15: 0.3875 | F15: canto de cada nível
A16: Cruzeta | B16: PP · 4 injetadas | C16: — | D16: 0.0566 | E16: 0.4951 | F16: só quando dois vãos dividem um poste (N ≥ 2)
A17: Peça L | B17: PP · molde existe | C17: — | D17: 0.032 | E17: 0.3003 | F17: coroa — só no módulo arara
A18: Tampa | B18: PP · molde existe | C18: — | D18: 0.0011 | E18: 0.0097 | F18: uma por poste
A20: Saem: painel de 200 (56,8% da curva, e é o que empena), painéis 200×634/754, 300×360, 460×360 e 460×450 (a regra da proporção 1,3–2,6), ripas PSC-01 (315) e PSC-03 (595), porta-haste.

Sheet Modulos
A1: Os 45 módulos padrão — 3 footprints × 3 larguras (N vãos) × 5 pilhas
A2: N = 1 é módulo autônomo (quatro postes próprios, zero cruzeta, dois adultos carregam). N = 2 e 3 dividem poste (cruzeta) e são para parede fixa. Filtre pela linha 4.
A4: ID | B4: Painel | C4: Ripa largura | D4: Ripa comprimento | E4: N vãos | F4: Pilha | G4: n 270 | H4: n 513 | I4: Coroa (mm) | J4: Prateleiras | K4: Comprimento (mm) | L4: Comprimento c/ coroa (mm) | M4: Profundidade (mm) | N4: Altura (mm) | O4: Face da última prat. (mm) | P4: Trizetas | Q4: Cruzetas | R4: Peças L | S4: Tampas | T4: Painéis | U4: Ripas compr. | V4: Ripas larg. | W4: Ripas 270 | X4: Ripas 513 | Y4: Pés | Z4: Massa (kg) | AA4: Custo material (R$) | AB4: Frente linear (m) | AC4: Altura ÷ prof. | AD4: Uso
A5: 300×450-1-baixo | B5: 300×450 | C5: 287 | D5: 415 | E5: 1 | F5: baixo · 270×3 | G5: 3 | H5: 0 | I5: 0 | J5: =G5+H5+1 -> 4 | K5: =2*Parametros!$C$6+(E5-1)*Parametros!$C$7+E5*(D5-Parametros!$C$13) -> 457.02 | L5: =IF(I5>0,K5+2*Parametros!$C$10,K5) -> 457.02 | M5: =C5+2*(Parametros!$C$8-Parametros!$C$5) -> 372.26 | N5: =Parametros!$C$11+(J5+IF(I5>0,1,0))*Parametros!$C$9+G5*(270-Parametros!$C$13)+H5*(513-Parametros!$C$13)+IF(I5>0,I5-Parametros!$C$13,0) -> 878.12 | O5: =Parametros!$C$11+J5*Parametros!$C$9+G5*(270-Parametros!$C$13)+H5*(513-Parametros!$C$13)+Parametros!$C$12/2 -> 885.62 | P5: =4*J5 -> 16 | Q5: =2*(E5-1)*(J5+IF(I5>0,1,0)) -> 0 | R5: =IF(I5>0,4,0) -> 0 | S5: =2*(E5+1) -> 4 | T5: =E5*J5 -> 4 | U5: =2*E5*J5+IF(I5>0,2*E5,0) -> 8 | V5: =(E5+1)*J5 -> 8 | W5: =2*(E5+1)*(G5+IF(I5=270,1,0)) -> 12 | X5: =2*(E5+1)*(H5+IF(I5=513,1,0)) -> 0 | Y5: =2*(E5+1) -> 4 | Z5: =P5*Kit!$D$15+Q5*Kit!$D$16+R5*Kit!$D$17+S5*Kit!$D$18+T5*Kit!$D$5+U5*Kit!$D$10+V5*Kit!$D$8+W5*Kit!$D$12+X5*Kit!$D$13+Y5*Kit!$D$14 -> 7.2748 | AA5: =P5*Kit!$E$15+Q5*Kit!$E$16+R5*Kit!$E$17+S5*Kit!$E$18+T5*Kit!$E$5+U5*Kit!$E$10+V5*Kit!$E$8+W5*Kit!$E$12+X5*Kit!$E$13+Y5*Kit!$E$14 -> 131.1104 | AB5: =K5*J5/1000 -> 1.82808 | AC5: =N5/M5 -> 2.3588889 | AD5: ilha, checkout, mesa de demonstração — vê-se por cima
A6: 300×450-1-médio | B6: 300×450 | C6: 287 | D6: 415 | E6: 1 | F6: médio · 270×5 | G6: 5 | H6: 0 | I6: 0 | J6: =G6+H6+1 -> 6 | K6: =2*Parametros!$C$6+(E6-1)*Parametros!$C$7+E6*(D6-Parametros!$C$13) -> 457.02 | L6: =IF(I6>0,K6+2*Parametros!$C$10,K6) -> 457.02 | M6: =C6+2*(Parametros!$C$8-Parametros!$C$5) -> 372.26 | N6: =Parametros!$C$11+(J6+IF(I6>0,1,0))*Parametros!$C$9+G6*(270-Parametros!$C$13)+H6*(513-Parametros!$C$13)+IF(I6>0,I6-Parametros!$C$13,0) -> 1401.88 | O6: =Parametros!$C$11+J6*Parametros!$C$9+G6*(270-Parametros!$C$13)+H6*(513-Parametros!$C$13)+Parametros!$C$12/2 -> 1409.38 | P6: =4*J6 -> 24 | Q6: =2*(E6-1)*(J6+IF(I6>0,1,0)) -> 0 | R6: =IF(I6>0,4,0) -> 0 | S6: =2*(E6+1) -> 4 | T6: =E6*J6 -> 6 | U6: =2*E6*J6+IF(I6>0,2*E6,0) -> 12 | V6: =(E6+1)*J6 -> 12 | W6: =2*(E6+1)*(G6+IF(I6=270,1,0)) -> 20 | X6: =2*(E6+1)*(H6+IF(I6=513,1,0)) -> 0 | Y6: =2*(E6+1) -> 4 | Z6: =P6*Kit!$D$15+Q6*Kit!$D$16+R6*Kit!$D$17+S6*Kit!$D$18+T6*Kit!$D$5+U6*Kit!$D$10+V6*Kit!$D$8+W6*Kit!$D$12+X6*Kit!$D$13+Y6*Kit!$D$14 -> 11.005 | AA6: =P6*Kit!$E$15+Q6*Kit!$E$16+R6*Kit!$E$17+S6*Kit!$E$18+T6*Kit!$E$5+U6*Kit!$E$10+V6*Kit!$E$8+W6*Kit!$E$12+X6*Kit!$E$13+Y6*Kit!$E$14 -> 198.4546 | AB6: =K6*J6/1000 -> 2.74212 | AC6: =N6/M6 -> 3.7658626 | AD6: gôndola de miolo, ponta
A7: 300×450-1-alto | B7: 300×450 | C7: 287 | D7: 415 | E7: 1 | F7: alto · 270×6 | G7: 6 | H7: 0 | I7: 0 | J7: =G7+H7+1 -> 7 | K7: =2*Parametros!$C$6+(E7-1)*Parametros!$C$7+E7*(D7-Parametros!$C$13) -> 457.02 | L7: =IF(I7>0,K7+2*Parametros!$C$10,K7) -> 457.02 | M7: =C7+2*(Parametros!$C$8-Parametros!$C$5) -> 372.26 | N7: =Parametros!$C$11+(J7+IF(I7>0,1,0))*Parametros!$C$9+G7*(270-Parametros!$C$13)+H7*(513-Parametros!$C$13)+IF(I7>0,I7-Parametros!$C$13,0) -> 1663.76 | O7: =Parametros!$C$11+J7*Parametros!$C$9+G7*(270-Parametros!$C$13)+H7*(513-Parametros!$C$13)+Parametros!$C$12/2 -> 1671.26 | P7: =4*J7 -> 28 | Q7: =2*(E7-1)*(J7+IF(I7>0,1,0)) -> 0 | R7: =IF(I7>0,4,0) -> 0 | S7: =2*(E7+1) -> 4 | T7: =E7*J7 -> 7 | U7: =2*E7*J7+IF(I7>0,2*E7,0) -> 14 | V7: =(E7+1)*J7 -> 14 | W7: =2*(E7+1)*(G7+IF(I7=270,1,0)) -> 24 | X7: =2*(E7+1)*(H7+IF(I7=513,1,0)) -> 0 | Y7: =2*(E7+1) -> 4 | Z7: =P7*Kit!$D$15+Q7*Kit!$D$16+R7*Kit!$D$17+S7*Kit!$D$18+T7*Kit!$D$5+U7*Kit!$D$10+V7*Kit!$D$8+W7*Kit!$D$12+X7*Kit!$D$13+Y7*Kit!$D$14 -> 12.8701 | AA7: =P7*Kit!$E$15+Q7*Kit!$E$16+R7*Kit!$E$17+S7*Kit!$E$18+T7*Kit!$E$5+U7*Kit!$E$10+V7*Kit!$E$8+W7*Kit!$E$12+X7*Kit!$E$13+Y7*Kit!$E$14 -> 232.1267 | AB7: =K7*J7/1000 -> 3.19914 | AC7: =N7/M7 -> 4.4693494 | AD7: parede: duas prateleiras na zona dos olhos
A8: 300×450-1-alto-fundo | B8: 300×450 | C8: 287 | D8: 415 | E8: 1 | F8: alto-fundo · 513·513·270·270 | G8: 2 | H8: 2 | I8: 0 | J8: =G8+H8+1 -> 5 | K8: =2*Parametros!$C$6+(E8-1)*Parametros!$C$7+E8*(D8-Parametros!$C$13) -> 457.02 | L8: =IF(I8>0,K8+2*Parametros!$C$10,K8) -> 457.02 | M8: =C8+2*(Parametros!$C$8-Parametros!$C$5) -> 372.26 | N8: =Parametros!$C$11+(J8+IF(I8>0,1,0))*Parametros!$C$9+G8*(270-Parametros!$C$13)+H8*(513-Parametros!$C$13)+IF(I8>0,I8-Parametros!$C$13,0) -> 1626 | O8: =Parametros!$C$11+J8*Parametros!$C$9+G8*(270-Parametros!$C$13)+H8*(513-Parametros!$C$13)+Parametros!$C$12/2 -> 1633.5 | P8: =4*J8 -> 20 | Q8: =2*(E8-1)*(J8+IF(I8>0,1,0)) -> 0 | R8: =IF(I8>0,4,0) -> 0 | S8: =2*(E8+1) -> 4 | T8: =E8*J8 -> 5 | U8: =2*E8*J8+IF(I8>0,2*E8,0) -> 10 | V8: =(E8+1)*J8 -> 10 | W8: =2*(E8+1)*(G8+IF(I8=270,1,0)) -> 8 | X8: =2*(E8+1)*(H8+IF(I8=513,1,0)) -> 8 | Y8: =2*(E8+1) -> 4 | Z8: =P8*Kit!$D$15+Q8*Kit!$D$16+R8*Kit!$D$17+S8*Kit!$D$18+T8*Kit!$D$5+U8*Kit!$D$10+V8*Kit!$D$8+W8*Kit!$D$12+X8*Kit!$D$13+Y8*Kit!$D$14 -> 9.5799 | AA8: =P8*Kit!$E$15+Q8*Kit!$E$16+R8*Kit!$E$17+S8*Kit!$E$18+T8*Kit!$E$5+U8*Kit!$E$10+V8*Kit!$E$8+W8*Kit!$E$12+X8*Kit!$E$13+Y8*Kit!$E$14 -> 173.1537 | AB8: =K8*J8/1000 -> 2.2851 | AC8: =N8/M8 -> 4.3679149 | AD8: parede de banho/lavanderia: vão de 490 embaixo para lixeira e cesto
A9: 300×450-1-arara | B9: 300×450 | C9: 287 | D9: 415 | E9: 1 | F9: arara · 513·513 + coroa 513 | G9: 0 | H9: 2 | I9: 513 | J9: =G9+H9+1 -> 3 | K9: =2*Parametros!$C$6+(E9-1)*Parametros!$C$7+E9*(D9-Parametros!$C$13) -> 457.02 | L9: =IF(I9>0,K9+2*Parametros!$C$10,K9) -> 500.86 | M9: =C9+2*(Parametros!$C$8-Parametros!$C$5) -> 372.26 | N9: =Parametros!$C$11+(J9+IF(I9>0,1,0))*Parametros!$C$9+G9*(270-Parametros!$C$13)+H9*(513-Parametros!$C$13)+IF(I9>0,I9-Parametros!$C$13,0) -> 1607.12 | O9: =Parametros!$C$11+J9*Parametros!$C$9+G9*(270-Parametros!$C$13)+H9*(513-Parametros!$C$13)+Parametros!$C$12/2 -> 1109.74 | P9: =4*J9 -> 12 | Q9: =2*(E9-1)*(J9+IF(I9>0,1,0)) -> 0 | R9: =IF(I9>0,4,0) -> 4 | S9: =2*(E9+1) -> 4 | T9: =E9*J9 -> 3 | U9: =2*E9*J9+IF(I9>0,2*E9,0) -> 8 | V9: =(E9+1)*J9 -> 6 | W9: =2*(E9+1)*(G9+IF(I9=270,1,0)) -> 0 | X9: =2*(E9+1)*(H9+IF(I9=513,1,0)) -> 12 | Y9: =2*(E9+1) -> 4 | Z9: =P9*Kit!$D$15+Q9*Kit!$D$16+R9*Kit!$D$17+S9*Kit!$D$18+T9*Kit!$D$5+U9*Kit!$D$10+V9*Kit!$D$8+W9*Kit!$D$12+X9*Kit!$D$13+Y9*Kit!$D$14 -> 6.6299 | AA9: =P9*Kit!$E$15+Q9*Kit!$E$16+R9*Kit!$E$17+S9*Kit!$E$18+T9*Kit!$E$5+U9*Kit!$E$10+V9*Kit!$E$8+W9*Kit!$E$12+X9*Kit!$E$13+Y9*Kit!$E$14 -> 119.4207 | AB9: =K9*J9/1000 -> 1.37106 | AC9: =N9/M9 -> 4.3171977 | AD9: arara e gancheira: a peça L fecha o topo sem prateleira
A10: 300×450-2-baixo | B10: 300×450 | C10: 287 | D10: 415 | E10: 2 | F10: baixo · 270×3 | G10: 3 | H10: 0 | I10: 0 | J10: =G10+H10+1 -> 4 | K10: =2*Parametros!$C$6+(E10-1)*Parametros!$C$7+E10*(D10-Parametros!$C$13) -> 892.12 | L10: =IF(I10>0,K10+2*Parametros!$C$10,K10) -> 892.12 | M10: =C10+2*(Parametros!$C$8-Parametros!$C$5) -> 372.26 | N10: =Parametros!$C$11+(J10+IF(I10>0,1,0))*Parametros!$C$9+G10*(270-Parametros!$C$13)+H10*(513-Parametros!$C$13)+IF(I10>0,I10-Parametros!$C$13,0) -> 878.12 | O10: =Parametros!$C$11+J10*Parametros!$C$9+G10*(270-Parametros!$C$13)+H10*(513-Parametros!$C$13)+Parametros!$C$12/2 -> 885.62 | P10: =4*J10 -> 16 | Q10: =2*(E10-1)*(J10+IF(I10>0,1,0)) -> 8 | R10: =IF(I10>0,4,0) -> 0 | S10: =2*(E10+1) -> 6 | T10: =E10*J10 -> 8 | U10: =2*E10*J10+IF(I10>0,2*E10,0) -> 16 | V10: =(E10+1)*J10 -> 12 | W10: =2*(E10+1)*(G10+IF(I10=270,1,0)) -> 18 | X10: =2*(E10+1)*(H10+IF(I10=513,1,0)) -> 0 | Y10: =2*(E10+1) -> 6 | Z10: =P10*Kit!$D$15+Q10*Kit!$D$16+R10*Kit!$D$17+S10*Kit!$D$18+T10*Kit!$D$5+U10*Kit!$D$10+V10*Kit!$D$8+W10*Kit!$D$12+X10*Kit!$D$13+Y10*Kit!$D$14 -> 13.638 | AA10: =P10*Kit!$E$15+Q10*Kit!$E$16+R10*Kit!$E$17+S10*Kit!$E$18+T10*Kit!$E$5+U10*Kit!$E$10+V10*Kit!$E$8+W10*Kit!$E$12+X10*Kit!$E$13+Y10*Kit!$E$14 -> 247.5262 | AB10: =K10*J10/1000 -> 3.56848 | AC10: =N10/M10 -> 2.3588889 | AD10: ilha, checkout, mesa de demonstração — vê-se por cima
A11: 300×450-2-médio | B11: 300×450 | C11: 287 | D11: 415 | E11: 2 | F11: médio · 270×5 | G11: 5 | H11: 0 | I11: 0 | J11: =G11+H11+1 -> 6 | K11: =2*Parametros!$C$6+(E11-1)*Parametros!$C$7+E11*(D11-Parametros!$C$13) -> 892.12 | L11: =IF(I11>0,K11+2*Parametros!$C$10,K11) -> 892.12 | M11: =C11+2*(Parametros!$C$8-Parametros!$C$5) -> 372.26 | N11: =Parametros!$C$11+(J11+IF(I11>0,1,0))*Parametros!$C$9+G11*(270-Parametros!$C$13)+H11*(513-Parametros!$C$13)+IF(I11>0,I11-Parametros!$C$13,0) -> 1401.88 | O11: =Parametros!$C$11+J11*Parametros!$C$9+G11*(270-Parametros!$C$13)+H11*(513-Parametros!$C$13)+Parametros!$C$12/2 -> 1409.38 | P11: =4*J11 -> 24 | Q11: =2*(E11-1)*(J11+IF(I11>0,1,0)) -> 12 | R11: =IF(I11>0,4,0) -> 0 | S11: =2*(E11+1) -> 6 | T11: =E11*J11 -> 12 | U11: =2*E11*J11+IF(I11>0,2*E11,0) -> 24 | V11: =(E11+1)*J11 -> 18 | W11: =2*(E11+1)*(G11+IF(I11=270,1,0)) -> 30 | X11: =2*(E11+1)*(H11+IF(I11=513,1,0)) -> 0 | Y11: =2*(E11+1) -> 6 | Z11: =P11*Kit!$D$15+Q11*Kit!$D$16+R11*Kit!$D$17+S11*Kit!$D$18+T11*Kit!$D$5+U11*Kit!$D$10+V11*Kit!$D$8+W11*Kit!$D$12+X11*Kit!$D$13+Y11*Kit!$D$14 -> 20.5962 | AA11: =P11*Kit!$E$15+Q11*Kit!$E$16+R11*Kit!$E$17+S11*Kit!$E$18+T11*Kit!$E$5+U11*Kit!$E$10+V11*Kit!$E$8+W11*Kit!$E$12+X11*Kit!$E$13+Y11*Kit!$E$14 -> 373.9728 | AB11: =K11*J11/1000 -> 5.35272 | AC11: =N11/M11 -> 3.7658626 | AD11: gôndola de miolo, ponta
A12: 300×450-2-alto | B12: 300×450 | C12: 287 | D12: 415 | E12: 2 | F12: alto · 270×6 | G12: 6 | H12: 0 | I12: 0 | J12: =G12+H12+1 -> 7 | K12: =2*Parametros!$C$6+(E12-1)*Parametros!$C$7+E12*(D12-Parametros!$C$13) -> 892.12 | L12: =IF(I12>0,K12+2*Parametros!$C$10,K12) -> 892.12 | M12: =C12+2*(Parametros!$C$8-Parametros!$C$5) -> 372.26 | N12: =Parametros!$C$11+(J12+IF(I12>0,1,0))*Parametros!$C$9+G12*(270-Parametros!$C$13)+H12*(513-Parametros!$C$13)+IF(I12>0,I12-Parametros!$C$13,0) -> 1663.76 | O12: =Parametros!$C$11+J12*Parametros!$C$9+G12*(270-Parametros!$C$13)+H12*(513-Parametros!$C$13)+Parametros!$C$12/2 -> 1671.26 | P12: =4*J12 -> 28 | Q12: =2*(E12-1)*(J12+IF(I12>0,1,0)) -> 14 | R12: =IF(I12>0,4,0) -> 0 | S12: =2*(E12+1) -> 6 | T12: =E12*J12 -> 14 | U12: =2*E12*J12+IF(I12>0,2*E12,0) -> 28 | V12: =(E12+1)*J12 -> 21 | W12: =2*(E12+1)*(G12+IF(I12=270,1,0)) -> 36 | X12: =2*(E12+1)*(H12+IF(I12=513,1,0)) -> 0 | Y12: =2*(E12+1) -> 6 | Z12: =P12*Kit!$D$15+Q12*Kit!$D$16+R12*Kit!$D$17+S12*Kit!$D$18+T12*Kit!$D$5+U12*Kit!$D$10+V12*Kit!$D$8+W12*Kit!$D$12+X12*Kit!$D$13+Y12*Kit!$D$14 -> 24.0753 | AA12: =P12*Kit!$E$15+Q12*Kit!$E$16+R12*Kit!$E$17+S12*Kit!$E$18+T12*Kit!$E$5+U12*Kit!$E$10+V12*Kit!$E$8+W12*Kit!$E$12+X12*Kit!$E$13+Y12*Kit!$E$14 -> 437.1961 | AB12: =K12*J12/1000 -> 6.24484 | AC12: =N12/M12 -> 4.4693494 | AD12: parede: duas prateleiras na zona dos olhos
A13: 300×450-2-alto-fundo | B13: 300×450 | C13: 287 | D13: 415 | E13: 2 | F13: alto-fundo · 513·513·270·270 | G13: 2 | H13: 2 | I13: 0 | J13: =G13+H13+1 -> 5 | K13: =2*Parametros!$C$6+(E13-1)*Parametros!$C$7+E13*(D13-Parametros!$C$13) -> 892.12 | L13: =IF(I13>0,K13+2*Parametros!$C$10,K13) -> 892.12 | M13: =C13+2*(Parametros!$C$8-Parametros!$C$5) -> 372.26 | N13: =Parametros!$C$11+(J13+IF(I13>0,1,0))*Parametros!$C$9+G13*(270-Parametros!$C$13)+H13*(513-Parametros!$C$13)+IF(I13>0,I13-Parametros!$C$13,0) -> 1626 | O13: =Parametros!$C$11+J13*Parametros!$C$9+G13*(270-Parametros!$C$13)+H13*(513-Parametros!$C$13)+Parametros!$C$12/2 -> 1633.5 | P13: =4*J13 -> 20 | Q13: =2*(E13-1)*(J13+IF(I13>0,1,0)) -> 10 | R13: =IF(I13>0,4,0) -> 0 | S13: =2*(E13+1) -> 6 | T13: =E13*J13 -> 10 | U13: =2*E13*J13+IF(I13>0,2*E13,0) -> 20 | V13: =(E13+1)*J13 -> 15 | W13: =2*(E13+1)*(G13+IF(I13=270,1,0)) -> 12 | X13: =2*(E13+1)*(H13+IF(I13=513,1,0)) -> 12 | Y13: =2*(E13+1) -> 6 | Z13: =P13*Kit!$D$15+Q13*Kit!$D$16+R13*Kit!$D$17+S13*Kit!$D$18+T13*Kit!$D$5+U13*Kit!$D$10+V13*Kit!$D$8+W13*Kit!$D$12+X13*Kit!$D$13+Y13*Kit!$D$14 -> 17.7771 | AA13: =P13*Kit!$E$15+Q13*Kit!$E$16+R13*Kit!$E$17+S13*Kit!$E$18+T13*Kit!$E$5+U13*Kit!$E$10+V13*Kit!$E$8+W13*Kit!$E$12+X13*Kit!$E$13+Y13*Kit!$E$14 -> 323.3063 | AB13: =K13*J13/1000 -> 4.4606 | AC13: =N13/M13 -> 4.3679149 | AD13: parede de banho/lavanderia: vão de 490 embaixo para lixeira e cesto
A14: 300×450-2-arara | B14: 300×450 | C14: 287 | D14: 415 | E14: 2 | F14: arara · 513·513 + coroa 513 | G14: 0 | H14: 2 | I14: 513 | J14: =G14+H14+1 -> 3 | K14: =2*Parametros!$C$6+(E14-1)*Parametros!$C$7+E14*(D14-Parametros!$C$13) -> 892.12 | L14: =IF(I14>0,K14+2*Parametros!$C$10,K14) -> 935.96 | M14: =C14+2*(Parametros!$C$8-Parametros!$C$5) -> 372.26 | N14: =Parametros!$C$11+(J14+IF(I14>0,1,0))*Parametros!$C$9+G14*(270-Parametros!$C$13)+H14*(513-Parametros!$C$13)+IF(I14>0,I14-Parametros!$C$13,0) -> 1607.12 | O14: =Parametros!$C$11+J14*Parametros!$C$9+G14*(270-Parametros!$C$13)+H14*(513-Parametros!$C$13)+Parametros!$C$12/2 -> 1109.74 | P14: =4*J14 -> 12 | Q14: =2*(E14-1)*(J14+IF(I14>0,1,0)) -> 8 | R14: =IF(I14>0,4,0) -> 4 | S14: =2*(E14+1) -> 6 | T14: =E14*J14 -> 6 | U14: =2*E14*J14+IF(I14>0,2*E14,0) -> 16 | V14: =(E14+1)*J14 -> 9 | W14: =2*(E14+1)*(G14+IF(I14=270,1,0)) -> 0 | X14: =2*(E14+1)*(H14+IF(I14=513,1,0)) -> 18 | Y14: =2*(E14+1) -> 6 | Z14: =P14*Kit!$D$15+Q14*Kit!$D$16+R14*Kit!$D$17+S14*Kit!$D$18+T14*Kit!$D$5+U14*Kit!$D$10+V14*Kit!$D$8+W14*Kit!$D$12+X14*Kit!$D$13+Y14*Kit!$D$14 -> 12.1323 | AA14: =P14*Kit!$E$15+Q14*Kit!$E$16+R14*Kit!$E$17+S14*Kit!$E$18+T14*Kit!$E$5+U14*Kit!$E$10+V14*Kit!$E$8+W14*Kit!$E$12+X14*Kit!$E$13+Y14*Kit!$E$14 -> 219.4531 | AB14: =K14*J14/1000 -> 2.67636 | AC14: =N14/M14 -> 4.3171977 | AD14: arara e gancheira: a peça L fecha o topo sem prateleira
A15: 300×450-3-baixo | B15: 300×450 | C15: 287 | D15: 415 | E15: 3 | F15: baixo · 270×3 | G15: 3 | H15: 0 | I15: 0 | J15: =G15+H15+1 -> 4 | K15: =2*Parametros!$C$6+(E15-1)*Parametros!$C$7+E15*(D15-Parametros!$C$13) -> 1327.22 | L15: =IF(I15>0,K15+2*Parametros!$C$10,K15) -> 1327.22 | M15: =C15+2*(Parametros!$C$8-Parametros!$C$5) -> 372.26 | N15: =Parametros!$C$11+(J15+IF(I15>0,1,0))*Parametros!$C$9+G15*(270-Parametros!$C$13)+H15*(513-Parametros!$C$13)+IF(I15>0,I15-Parametros!$C$13,0) -> 878.12 | O15: =Parametros!$C$11+J15*Parametros!$C$9+G15*(270-Parametros!$C$13)+H15*(513-Parametros!$C$13)+Parametros!$C$12/2 -> 885.62 | P15: =4*J15 -> 16 | Q15: =2*(E15-1)*(J15+IF(I15>0,1,0)) -> 16 | R15: =IF(I15>0,4,0) -> 0 | S15: =2*(E15+1) -> 8 | T15: =E15*J15 -> 12 | U15: =2*E15*J15+IF(I15>0,2*E15,0) -> 24 | V15: =(E15+1)*J15 -> 16 | W15: =2*(E15+1)*(G15+IF(I15=270,1,0)) -> 24 | X15: =2*(E15+1)*(H15+IF(I15=513,1,0)) -> 0 | Y15: =2*(E15+1) -> 8 | Z15: =P15*Kit!$D$15+Q15*Kit!$D$16+R15*Kit!$D$17+S15*Kit!$D$18+T15*Kit!$D$5+U15*Kit!$D$10+V15*Kit!$D$8+W15*Kit!$D$12+X15*Kit!$D$13+Y15*Kit!$D$14 -> 20.0012 | AA15: =P15*Kit!$E$15+Q15*Kit!$E$16+R15*Kit!$E$17+S15*Kit!$E$18+T15*Kit!$E$5+U15*Kit!$E$10+V15*Kit!$E$8+W15*Kit!$E$12+X15*Kit!$E$13+Y15*Kit!$E$14 -> 363.942 | AB15: =K15*J15/1000 -> 5.30888 | AC15: =N15/M15 -> 2.3588889 | AD15: ilha, checkout, mesa de demonstração — vê-se por cima
A16: 300×450-3-médio | B16: 300×450 | C16: 287 | D16: 415 | E16: 3 | F16: médio · 270×5 | G16: 5 | H16: 0 | I16: 0 | J16: =G16+H16+1 -> 6 | K16: =2*Parametros!$C$6+(E16-1)*Parametros!$C$7+E16*(D16-Parametros!$C$13) -> 1327.22 | L16: =IF(I16>0,K16+2*Parametros!$C$10,K16) -> 1327.22 | M16: =C16+2*(Parametros!$C$8-Parametros!$C$5) -> 372.26 | N16: =Parametros!$C$11+(J16+IF(I16>0,1,0))*Parametros!$C$9+G16*(270-Parametros!$C$13)+H16*(513-Parametros!$C$13)+IF(I16>0,I16-Parametros!$C$13,0) -> 1401.88 | O16: =Parametros!$C$11+J16*Parametros!$C$9+G16*(270-Parametros!$C$13)+H16*(513-Parametros!$C$13)+Parametros!$C$12/2 -> 1409.38 | P16: =4*J16 -> 24 | Q16: =2*(E16-1)*(J16+IF(I16>0,1,0)) -> 24 | R16: =IF(I16>0,4,0) -> 0 | S16: =2*(E16+1) -> 8 | T16: =E16*J16 -> 18 | U16: =2*E16*J16+IF(I16>0,2*E16,0) -> 36 | V16: =(E16+1)*J16 -> 24 | W16: =2*(E16+1)*(G16+IF(I16=270,1,0)) -> 40 | X16: =2*(E16+1)*(H16+IF(I16=513,1,0)) -> 0 | Y16: =2*(E16+1) -> 8 | Z16: =P16*Kit!$D$15+Q16*Kit!$D$16+R16*Kit!$D$17+S16*Kit!$D$18+T16*Kit!$D$5+U16*Kit!$D$10+V16*Kit!$D$8+W16*Kit!$D$12+X16*Kit!$D$13+Y16*Kit!$D$14 -> 30.1874 | AA16: =P16*Kit!$E$15+Q16*Kit!$E$16+R16*Kit!$E$17+S16*Kit!$E$18+T16*Kit!$E$5+U16*Kit!$E$10+V16*Kit!$E$8+W16*Kit!$E$12+X16*Kit!$E$13+Y16*Kit!$E$14 -> 549.491 | AB16: =K16*J16/1000 -> 7.96332 | AC16: =N16/M16 -> 3.7658626 | AD16: gôndola de miolo, ponta
... A19: 300×450-3-arara | B19: 300×450 | C19: 287 | D19: 415 | E19: 3 | F19: arara · 513·513 + coroa 513 | G19: 0 | H19: 2 | I19: 513 | J19: =G19+H19+1 -> 3 | K19: =2*Parametros!$C$6+(E19-1)*Parametros!$C$7+E19*(D19-Parametros!$C$13) -> 1327.22 | L19: =IF(I19>0,K19+2*Parametros!$C$10,K19) -> 1371.06 | M19: =C19+2*(Parametros!$C$8-Parametros!$C$5) -> 372.26 | N19: =Parametros!$C$11+(J19+IF(I19>0,1,0))*Parametros!$C$9+G19*(270-Parametros!$C$13)+H19*(513-Parametros!$C$13)+IF(I19>0,I19-Parametros!$C$13,0) -> 1607.12 | O19: =Parametros!$C$11+J19*Parametros!$C$9+G19*(270-Parametros!$C$13)+H19*(513-Parametros!$C$13)+Parametros!$C$12/2 -> 1109.74 | P19: =4*J19 -> 12 | Q19: =2*(E19-1)*(J19+IF(I19>0,1,0)) -> 16 | R19: =IF(I19>0,4,0) -> 4 | S19: =2*(E19+1) -> 8 | T19: =E19*J19 -> 9 | U19: =2*E19*J19+IF(I19>0,2*E19,0) -> 24 | V19: =(E19+1)*J19 -> 12 | W19: =2*(E19+1)*(G19+IF(I19=270,1,0)) -> 0 | X19: =2*(E19+1)*(H19+IF(I19=513,1,0)) -> 24 | Y19: =2*(E19+1) -> 8 | Z19: =P19*Kit!$D$15+Q19*Kit!$D$16+R19*Kit!$D$17+S19*Kit!$D$18+T19*Kit!$D$5+U19*Kit!$D$10+V19*Kit!$D$8+W19*Kit!$D$12+X19*Kit!$D$13+Y19*Kit!$D$14 -> 17.6347 | AA19: =P19*Kit!$E$15+Q19*Kit!$E$16+R19*Kit!$E$17+S19*Kit!$E$18+T19*Kit!$E$5+U19*Kit!$E$10+V19*Kit!$E$8+W19*Kit!$E$12+X19*Kit!$E$13+Y19*Kit!$E$14 -> 319.4855 | AB19: =K19*J19/1000 -> 3.98166 | AC19: =N19/M19 -> 4.3171977 | AD19: arara e gancheira: a peça L fecha o topo sem prateleira
A20: 300×754-1-baixo | B20: 300×754 | C20: 287 | D20: 717 | E20: 1 | F20: baixo · 270×3 | G20: 3 | H20: 0 | I20: 0 | J20: =G20+H20+1 -> 4 | K20: =2*Parametros!$C$6+(E20-1)*Parametros!$C$7+E20*(D20-Parametros!$C$13) -> 759.02 | L20: =IF(I20>0,K20+2*Parametros!$C$10,K20) -> 759.02 | M20: =C20+2*(Parametros!$C$8-Parametros!$C$5) -> 372.26 | N20: =Parametros!$C$11+(J20+IF(I20>0,1,0))*Parametros!$C$9+G20*(270-Parametros!$C$13)+H20*(513-Parametros!$C$13)+IF(I20>0,I20-Parametros!$C$13,0) -> 878.12 | O20: =Parametros!$C$11+J20*Parametros!$C$9+G20*(270-Parametros!$C$13)+H20*(513-Parametros!$C$13)+Parametros!$C$12/2 -> 885.62 | P20: =4*J20 -> 16 | Q20: =2*(E20-1)*(J20+IF(I20>0,1,0)) -> 0 | R20: =IF(I20>0,4,0) -> 0 | S20: =2*(E20+1) -> 4 | T20: =E20*J20 -> 4 | U20: =2*E20*J20+IF(I20>0,2*E20,0) -> 8 | V20: =(E20+1)*J20 -> 8 | W20: =2*(E20+1)*(G20+IF(I20=270,1,0)) -> 12 | X20: =2*(E20+1)*(H20+IF(I20=513,1,0)) -> 0 | Y20: =2*(E20+1) -> 4 | Z20: =P20*Kit!$D$15+Q20*Kit!$D$16+R20*Kit!$D$17+S20*Kit!$D$18+T20*Kit!$D$6+U20*Kit!$D$11+V20*Kit!$D$8+W20*Kit!$D$12+X20*Kit!$D$13+Y20*Kit!$D$14 -> 10.8636 | AA20: =P20*Kit!$E$15+Q20*Kit!$E$16+R20*Kit!$E$17+S20*Kit!$E$18+T20*Kit!$E$6+U20*Kit!$E$11+V20*Kit!$E$8+W20*Kit!$E$12+X20*Kit!$E$13+Y20*Kit!$E$14 -> 199.4116 | AB20: =K20*J20/1000 -> 3.03608 | AC20: =N20/M20 -> 2.3588889 | AD20: ilha, checkout, mesa de demonstração — vê-se por cima
A21: 300×754-1-médio | B21: 300×754 | C21: 287 | D21: 717 | E21: 1 | F21: médio · 270×5 | G21: 5 | H21: 0 | I21: 0 | J21: =G21+H21+1 -> 6 | K21: =2*Parametros!$C$6+(E21-1)*Parametros!$C$7+E21*(D21-Parametros!$C$13) -> 759.02 | L21: =IF(I21>0,K21+2*Parametros!$C$10,K21) -> 759.02 | M21: =C21+2*(Parametros!$C$8-Parametros!$C$5) -> 372.26 | N21: =Parametros!$C$11+(J21+IF(I21>0,1,0))*Parametros!$C$9+G21*(270-Parametros!$C$13)+H21*(513-Parametros!$C$13)+IF(I21>0,I21-Parametros!$C$13,0) -> 1401.88 | O21: =Parametros!$C$11+J21*Parametros!$C$9+G21*(270-Parametros!$C$13)+H21*(513-Parametros!$C$13)+Parametros!$C$12/2 -> 1409.38 | P21: =4*J21 -> 24 | Q21: =2*(E21-1)*(J21+IF(I21>0,1,0)) -> 0 | R21: =IF(I21>0,4,0) -> 0 | S21: =2*(E21+1) -> 4 | T21: =E21*J21 -> 6 | U21: =2*E21*J21+IF(I21>0,2*E21,0) -> 12 | V21: =(E21+1)*J21 -> 12 | W21: =2*(E21+1)*(G21+IF(I21=270,1,0)) -> 20 | X21: =2*(E21+1)*(H21+IF(I21=513,1,0)) -> 0 | Y21: =2*(E21+1) -> 4 | Z21: =P21*Kit!$D$15+Q21*Kit!$D$16+R21*Kit!$D$17+S21*Kit!$D$18+T21*Kit!$D$6+U21*Kit!$D$11+V21*Kit!$D$8+W21*Kit!$D$12+X21*Kit!$D$13+Y21*Kit!$D$14 -> 16.3882 | AA21: =P21*Kit!$E$15+Q21*Kit!$E$16+R21*Kit!$E$17+S21*Kit!$E$18+T21*Kit!$E$6+U21*Kit!$E$11+V21*Kit!$E$8+W21*Kit!$E$12+X21*Kit!$E$13+Y21*Kit!$E$14 -> 300.9064 | AB21: =K21*J21/1000 -> 4.55412 | AC21: =N21/M21 -> 3.7658626 | AD21: gôndola de miolo, ponta
A22: 300×754-1-alto | B22: 300×754 | C22: 287 | D22: 717 | E22: 1 | F22: alto · 270×6 | G22: 6 | H22: 0 | I22: 0 | J22: =G22+H22+1 -> 7 | K22: =2*Parametros!$C$6+(E22-1)*Parametros!$C$7+E22*(D22-Parametros!$C$13) -> 759.02 | L22: =IF(I22>0,K22+2*Parametros!$C$10,K22) -> 759.02 | M22: =C22+2*(Parametros!$C$8-Parametros!$C$5) -> 372.26 | N22: =Parametros!$C$11+(J22+IF(I22>0,1,0))*Parametros!$C$9+G22*(270-Parametros!$C$13)+H22*(513-Parametros!$C$13)+IF(I22>0,I22-Parametros!$C$13,0) -> 1663.76 | O22: =Parametros!$C$11+J22*Parametros!$C$9+G22*(270-Parametros!$C$13)+H22*(513-Parametros!$C$13)+Parametros!$C$12/2 -> 1671.26 | P22: =4*J22 -> 28 | Q22: =2*(E22-1)*(J22+IF(I22>0,1,0)) -> 0 | R22: =IF(I22>0,4,0) -> 0 | S22: =2*(E22+1) -> 4 | T22: =E22*J22 -> 7 | U22: =2*E22*J22+IF(I22>0,2*E22,0) -> 14 | V22: =(E22+1)*J22 -> 14 | W22: =2*(E22+1)*(G22+IF(I22=270,1,0)) -> 24 | X22: =2*(E22+1)*(H22+IF(I22=513,1,0)) -> 0 | Y22: =2*(E22+1) -> 4 | Z22: =P22*Kit!$D$15+Q22*Kit!$D$16+R22*Kit!$D$17+S22*Kit!$D$18+T22*Kit!$D$6+U22*Kit!$D$11+V22*Kit!$D$8+W22*Kit!$D$12+X22*Kit!$D$13+Y22*Kit!$D$14 -> 19.1505 | AA22: =P22*Kit!$E$15+Q22*Kit!$E$16+R22*Kit!$E$17+S22*Kit!$E$18+T22*Kit!$E$6+U22*Kit!$E$11+V22*Kit!$E$8+W22*Kit!$E$12+X22*Kit!$E$13+Y22*Kit!$E$14 -> 351.6538 | AB22: =K22*J22/1000 -> 5.31314 | AC22: =N22/M22 -> 4.4693494 | AD22: parede: duas prateleiras na zona dos olhos
A23: 300×754-1-alto-fundo | B23: 300×754 | C23: 287 | D23: 717 | E23: 1 | F23: alto-fundo · 513·513·270·270 | G23: 2 | H23: 2 | I23: 0 | J23: =G23+H23+1 -> 5 | K23: =2*Parametros!$C$6+(E23-1)*Parametros!$C$7+E23*(D23-Parametros!$C$13) -> 759.02 | L23: =IF(I23>0,K23+2*Parametros!$C$10,K23) -> 759.02 | M23: =C23+2*(Parametros!$C$8-Parametros!$C$5) -> 372.26 | N23: =Parametros!$C$11+(J23+IF(I23>0,1,0))*Parametros!$C$9+G23*(270-Parametros!$C$13)+H23*(513-Parametros!$C$13)+IF(I23>0,I23-Parametros!$C$13,0) -> 1626 | O23: =Parametros!$C$11+J23*Parametros!$C$9+G23*(270-Parametros!$C$13)+H23*(513-Parametros!$C$13)+Parametros!$C$12/2 -> 1633.5 | P23: =4*J23 -> 20 | Q23: =2*(E23-1)*(J23+IF(I23>0,1,0)) -> 0 | R23: =IF(I23>0,4,0) -> 0 | S23: =2*(E23+1) -> 4 | T23: =E23*J23 -> 5 | U23: =2*E23*J23+IF(I23>0,2*E23,0) -> 10 | V23: =(E23+1)*J23 -> 10 | W23: =2*(E23+1)*(G23+IF(I23=270,1,0)) -> 8 | X23: =2*(E23+1)*(H23+IF(I23=513,1,0)) -> 8 | Y23: =2*(E23+1) -> 4 | Z23: =P23*Kit!$D$15+Q23*Kit!$D$16+R23*Kit!$D$17+S23*Kit!$D$18+T23*Kit!$D$6+U23*Kit!$D$11+V23*Kit!$D$8+W23*Kit!$D$12+X23*Kit!$D$13+Y23*Kit!$D$14 -> 14.0659 | AA23: =P23*Kit!$E$15+Q23*Kit!$E$16+R23*Kit!$E$17+S23*Kit!$E$18+T23*Kit!$E$6+U23*Kit!$E$11+V23*Kit!$E$8+W23*Kit!$E$12+X23*Kit!$E$13+Y23*Kit!$E$14 -> 258.5302 | AB23: =K23*J23/1000 -> 3.7951 | AC23: =N23/M23 -> 4.3679149 | AD23: parede de banho/lavanderia: vão de 490 embaixo para lixeira e cesto
A24: 300×754-1-arara | B24: 300×754 | C24: 287 | D24: 717 | E24: 1 | F24: arara · 513·513 + coroa 513 | G24: 0 | H24: 2 | I24: 513 | J24: =G24+H24+1 -> 3 | K24: =2*Parametros!$C$6+(E24-1)*Parametros!$C$7+E24*(D24-Parametros!$C$13) -> 759.02 | L24: =IF(I24>0,K24+2*Parametros!$C$10,K24) -> 802.86 | M24: =C24+2*(Parametros!$C$8-Parametros!$C$5) -> 372.26 | N24: =Parametros!$C$11+(J24+IF(I24>0,1,0))*Parametros!$C$9+G24*(270-Parametros!$C$13)+H24*(513-Parametros!$C$13)+IF(I24>0,I24-Parametros!$C$13,0) -> 1607.12 | O24: =Parametros!$C$11+J24*Parametros!$C$9+G24*(270-Parametros!$C$13)+H24*(513-Parametros!$C$13)+Parametros!$C$12/2 -> 1109.74 | P24: =4*J24 -> 12 | Q24: =2*(E24-1)*(J24+IF(I24>0,1,0)) -> 0 | R24: =IF(I24>0,4,0) -> 4 | S24: =2*(E24+1) -> 4 | T24: =E24*J24 -> 3 | U24: =2*E24*J24+IF(I24>0,2*E24,0) -> 8 | V24: =(E24+1)*J24 -> 6 | W24: =2*(E24+1)*(G24+IF(I24=270,1,0)) -> 0 | X24: =2*(E24+1)*(H24+IF(I24=513,1,0)) -> 12 | Y24: =2*(E24+1) -> 4 | Z24: =P24*Kit!$D$15+Q24*Kit!$D$16+R24*Kit!$D$17+S24*Kit!$D$18+T24*Kit!$D$6+U24*Kit!$D$11+V24*Kit!$D$8+W24*Kit!$D$12+X24*Kit!$D$13+Y24*Kit!$D$14 -> 9.4581 | AA24: =P24*Kit!$E$15+Q24*Kit!$E$16+R24*Kit!$E$17+S24*Kit!$E$18+T24*Kit!$E$6+U24*Kit!$E$11+V24*Kit!$E$8+W24*Kit!$E$12+X24*Kit!$E$13+Y24*Kit!$E$14 -> 173.2476 | AB24: =K24*J24/1000 -> 2.27706 | AC24: =N24/M24 -> 4.3171977 | AD24: arara e gancheira: a peça L fecha o topo sem prateleira
A25: 300×754-2-baixo | B25: 300×754 | C25: 287 | D25: 717 | E25: 2 | F25: baixo · 270×3 | G25: 3 | H25: 0 | I25: 0 | J25: =G25+H25+1 -> 4 | K25: =2*Parametros!$C$6+(E25-1)*Parametros!$C$7+E25*(D25-Parametros!$C$13) -> 1496.12 | L25: =IF(I25>0,K25+2*Parametros!$C$10,K25) -> 1496.12 | M25: =C25+2*(Parametros!$C$8-Parametros!$C$5) -> 372.26 | N25: =Parametros!$C$11+(J25+IF(I25>0,1,0))*Parametros!$C$9+G25*(270-Parametros!$C$13)+H25*(513-Parametros!$C$13)+IF(I25>0,I25-Parametros!$C$13,0) -> 878.12 | O25: =Parametros!$C$11+J25*Parametros!$C$9+G25*(270-Parametros!$C$13)+H25*(513-Parametros!$C$13)+Parametros!$C$12/2 -> 885.62 | P25: =4*J25 -> 16 | Q25: =2*(E25-1)*(J25+IF(I25>0,1,0)) -> 8 | R25: =IF(I25>0,4,0) -> 0 | S25: =2*(E25+1) -> 6 | T25: =E25*J25 -> 8 | U25: =2*E25*J25+IF(I25>0,2*E25,0) -> 16 | V25: =(E25+1)*J25 -> 12 | W25: =2*(E25+1)*(G25+IF(I25=270,1,0)) -> 18 | X25: =2*(E25+1)*(H25+IF(I25=513,1,0)) -> 0 | Y25: =2*(E25+1) -> 6 | Z25: =P25*Kit!$D$15+Q25*Kit!$D$16+R25*Kit!$D$17+S25*Kit!$D$18+T25*Kit!$D$6+U25*Kit!$D$11+V25*Kit!$D$8+W25*Kit!$D$12+X25*Kit!$D$13+Y25*Kit!$D$14 -> 20.8156 | AA25: =P25*Kit!$E$15+Q25*Kit!$E$16+R25*Kit!$E$17+S25*Kit!$E$18+T25*Kit!$E$6+U25*Kit!$E$11+V25*Kit!$E$8+W25*Kit!$E$12+X25*Kit!$E$13+Y25*Kit!$E$14 -> 384.1286 | AB25: =K25*J25/1000 -> 5.98448 | AC25: =N25/M25 -> 2.3588889 | AD25: ilha, checkout, mesa de demonstração — vê-se por cima
A26: 300×754-2-médio | B26: 300×754 | C26: 287 | D26: 717 | E26: 2 | F26: médio · 270×5 | G26: 5 | H26: 0 | I26: 0 | J26: =G26+H26+1 -> 6 | K26: =2*Parametros!$C$6+(E26-1)*Parametros!$C$7+E26*(D26-Parametros!$C$13) -> 1496.12 | L26: =IF(I26>0,K26+2*Parametros!$C$10,K26) -> 1496.12 | M26: =C26+2*(Parametros!$C$8-Parametros!$C$5) -> 372.26 | N26: =Parametros!$C$11+(J26+IF(I26>0,1,0))*Parametros!$C$9+G26*(270-Parametros!$C$13)+H26*(513-Parametros!$C$13)+IF(I26>0,I26-Parametros!$C$13,0) -> 1401.88 | O26: =Parametros!$C$11+J26*Parametros!$C$9+G26*(270-Parametros!$C$13)+H26*(513-Parametros!$C$13)+Parametros!$C$12/2 -> 1409.38 | P26: =4*J26 -> 24 | Q26: =2*(E26-1)*(J26+IF(I26>0,1,0)) -> 12 | R26: =IF(I26>0,4,0) -> 0 | S26: =2*(E26+1) -> 6 | T26: =E26*J26 -> 12 | U26: =2*E26*J26+IF(I26>0,2*E26,0) -> 24 | V26: =(E26+1)*J26 -> 18 | W26: =2*(E26+1)*(G26+IF(I26=270,1,0)) -> 30 | X26: =2*(E26+1)*(H26+IF(I26=513,1,0)) -> 0 | Y26: =2*(E26+1) -> 6 | Z26: =P26*Kit!$D$15+Q26*Kit!$D$16+R26*Kit!$D$17+S26*Kit!$D$18+T26*Kit!$D$6+U26*Kit!$D$11+V26*Kit!$D$8+W26*Kit!$D$12+X26*Kit!$D$13+Y26*Kit!$D$14 -> 31.3626 | AA26: =P26*Kit!$E$15+Q26*Kit!$E$16+R26*Kit!$E$17+S26*Kit!$E$18+T26*Kit!$E$6+U26*Kit!$E$11+V26*Kit!$E$8+W26*Kit!$E$12+X26*Kit!$E$13+Y26*Kit!$E$14 -> 578.8764 | AB26: =K26*J26/1000 -> 8.97672 | AC26: =N26/M26 -> 3.7658626 | AD26: gôndola de miolo, ponta
A27: 300×754-2-alto | B27: 300×754 | C27: 287 | D27: 717 | E27: 2 | F27: alto · 270×6 | G27: 6 | H27: 0 | I27: 0 | J27: =G27+H27+1 -> 7 | K27: =2*Parametros!$C$6+(E27-1)*Parametros!$C$7+E27*(D27-Parametros!$C$13) -> 1496.12 | L27: =IF(I27>0,K27+2*Parametros!$C$10,K27) -> 1496.12 | M27: =C27+2*(Parametros!$C$8-Parametros!$C$5) -> 372.26 | N27: =Parametros!$C$11+(J27+IF(I27>0,1,0))*Parametros!$C$9+G27*(270-Parametros!$C$13)+H27*(513-Parametros!$C$13)+IF(I27>0,I27-Parametros!$C$13,0) -> 1663.76 | O27: =Parametros!$C$11+J27*Parametros!$C$9+G27*(270-Parametros!$C$13)+H27*(513-Parametros!$C$13)+Parametros!$C$12/2 -> 1671.26 | P27: =4*J27 -> 28 | Q27: =2*(E27-1)*(J27+IF(I27>0,1,0)) -> 14 | R27: =IF(I27>0,4,0) -> 0 | S27: =2*(E27+1) -> 6 | T27: =E27*J27 -> 14 | U27: =2*E27*J27+IF(I27>0,2*E27,0) -> 28 | V27: =(E27+1)*J27 -> 21 | W27: =2*(E27+1)*(G27+IF(I27=270,1,0)) -> 36 | X27: =2*(E27+1)*(H27+IF(I27=513,1,0)) -> 0 | Y27: =2*(E27+1) -> 6 | Z27: =P27*Kit!$D$15+Q27*Kit!$D$16+R27*Kit!$D$17+S27*Kit!$D$18+T27*Kit!$D$6+U27*Kit!$D$11+V27*Kit!$D$8+W27*Kit!$D$12+X27*Kit!$D$13+Y27*Kit!$D$14 -> 36.6361 | AA27: =P27*Kit!$E$15+Q27*Kit!$E$16+R27*Kit!$E$17+S27*Kit!$E$18+T27*Kit!$E$6+U27*Kit!$E$11+V27*Kit!$E$8+W27*Kit!$E$12+X27*Kit!$E$13+Y27*Kit!$E$14 -> 676.2503 | AB27: =K27*J27/1000 -> 10.47284 | AC27: =N27/M27 -> 4.4693494 | AD27: parede: duas prateleiras na zona dos olhos
A28: 300×754-2-alto-fundo | B28: 300×754 | C28: 287 | D28: 717 | E28: 2 | F28: alto-fundo · 513·513·270·270 | G28: 2 | H28: 2 | I28: 0 | J28: =G28+H28+1 -> 5 | K28: =2*Parametros!$C$6+(E28-1)*Parametros!$C$7+E28*(D28-Parametros!$C$13) -> 1496.12 | L28: =IF(I28>0,K28+2*Parametros!$C$10,K28) -> 1496.12 | M28: =C28+2*(Parametros!$C$8-Parametros!$C$5) -> 372.26 | N28: =Parametros!$C$11+(J28+IF(I28>0,1,0))*Parametros!$C$9+G28*(270-Parametros!$C$13)+H28*(513-Parametros!$C$13)+IF(I28>0,I28-Parametros!$C$13,0) -> 1626 | O28: =Parametros!$C$11+J28*Parametros!$C$9+G28*(270-Parametros!$C$13)+H28*(513-Parametros!$C$13)+Parametros!$C$12/2 -> 1633.5 | P28: =4*J28 -> 20 | Q28: =2*(E28-1)*(J28+IF(I28>0,1,0)) -> 10 | R28: =IF(I28>0,4,0) -> 0 | S28: =2*(E28+1) -> 6 | T28: =E28*J28 -> 10 | U28: =2*E28*J28+IF(I28>0,2*E28,0) -> 20 | V28: =(E28+1)*J28 -> 15 | W28: =2*(E28+1)*(G28+IF(I28=270,1,0)) -> 12 | X28: =2*(E28+1)*(H28+IF(I28=513,1,0)) -> 12 | Y28: =2*(E28+1) -> 6 | Z28: =P28*Kit!$D$15+Q28*Kit!$D$16+R28*Kit!$D$17+S28*Kit!$D$18+T28*Kit!$D$6+U28*Kit!$D$11+V28*Kit!$D$8+W28*Kit!$D$12+X28*Kit!$D$13+Y28*Kit!$D$14 -> 26.7491 | AA28: =P28*Kit!$E$15+Q28*Kit!$E$16+R28*Kit!$E$17+S28*Kit!$E$18+T28*Kit!$E$6+U28*Kit!$E$11+V28*Kit!$E$8+W28*Kit!$E$12+X28*Kit!$E$13+Y28*Kit!$E$14 -> 494.0593 | AB28: =K28*J28/1000 -> 7.4806 | AC28: =N28/M28 -> 4.3679149 | AD28: parede de banho/lavanderia: vão de 490 embaixo para lixeira e cesto
A29: 300×754-2-arara | B29: 300×754 | C29: 287 | D29: 717 | E29: 2 | F29: arara · 513·513 + coroa 513 | G29: 0 | H29: 2 | I29: 513 | J29: =G29+H29+1 -> 3 | K29: =2*Parametros!$C$6+(E29-1)*Parametros!$C$7+E29*(D29-Parametros!$C$13) -> 1496.12 | L29: =IF(I29>0,K29+2*Parametros!$C$10,K29) -> 1539.96 | M29: =C29+2*(Parametros!$C$8-Parametros!$C$5) -> 372.26 | N29: =Parametros!$C$11+(J29+IF(I29>0,1,0))*Parametros!$C$9+G29*(270-Parametros!$C$13)+H29*(513-Parametros!$C$13)+IF(I29>0,I29-Parametros!$C$13,0) -> 1607.12 | O29: =Parametros!$C$11+J29*Parametros!$C$9+G29*(270-Parametros!$C$13)+H29*(513-Parametros!$C$13)+Parametros!$C$12/2 -> 1109.74 | P29: =4*J29 -> 12 | Q29: =2*(E29-1)*(J29+IF(I29>0,1,0)) -> 8 | R29: =IF(I29>0,4,0) -> 4 | S29: =2*(E29+1) -> 6 | T29: =E29*J29 -> 6 | U29: =2*E29*J29+IF(I29>0,2*E29,0) -> 16 | V29: =(E29+1)*J29 -> 9 | W29: =2*(E29+1)*(G29+IF(I29=270,1,0)) -> 0 | X29: =2*(E29+1)*(H29+IF(I29=513,1,0)) -> 18 | Y29: =2*(E29+1) -> 6 | Z29: =P29*Kit!$D$15+Q29*Kit!$D$16+R29*Kit!$D$17+S29*Kit!$D$18+T29*Kit!$D$6+U29*Kit!$D$11+V29*Kit!$D$8+W29*Kit!$D$12+X29*Kit!$D$13+Y29*Kit!$D$14 -> 17.7887 | AA29: =P29*Kit!$E$15+Q29*Kit!$E$16+R29*Kit!$E$17+S29*Kit!$E$18+T29*Kit!$E$6+U29*Kit!$E$11+V29*Kit!$E$8+W29*Kit!$E$12+X29*Kit!$E$13+Y29*Kit!$E$14 -> 327.1069 | AB29: =K29*J29/1000 -> 4.48836 | AC29: =N29/M29 -> 4.3171977 | AD29: arara e gancheira: a peça L fecha o topo sem prateleira
A30: 300×754-3-baixo | B30: 300×754 | C30: 287 | D30: 717 | E30: 3 | F30: baixo · 270×3 | G30: 3 | H30: 0 | I30: 0 | J30: =G30+H30+1 -> 4 | K30: =2*Parametros!$C$6+(E30-1)*Parametros!$C$7+E30*(D30-Parametros!$C$13) -> 2233.22 | L30: =IF(I30>0,K30+2*Parametros!$C$10,K30) -> 2233.22 | M30: =C30+2*(Parametros!$C$8-Parametros!$C$5) -> 372.26 | N30: =Parametros!$C$11+(J30+IF(I30>0,1,0))*Parametros!$C$9+G30*(270-Parametros!$C$13)+H30*(513-Parametros!$C$13)+IF(I30>0,I30-Parametros!$C$13,0) -> 878.12 | O30: =Parametros!$C$11+J30*Parametros!$C$9+G30*(270-Parametros!$C$13)+H30*(513-Parametros!$C$13)+Parametros!$C$12/2 -> 885.62 | P30: =4*J30 -> 16 | Q30: =2*(E30-1)*(J30+IF(I30>0,1,0)) -> 16 | R30: =IF(I30>0,4,0) -> 0 | S30: =2*(E30+1) -> 8 | T30: =E30*J30 -> 12 | U30: =2*E30*J30+IF(I30>0,2*E30,0) -> 24 | V30: =(E30+1)*J30 -> 16 | W30: =2*(E30+1)*(G30+IF(I30=270,1,0)) -> 24 | X30: =2*(E30+1)*(H30+IF(I30=513,1,0)) -> 0 | Y30: =2*(E30+1) -> 8 | Z30: =P30*Kit!$D$15+Q30*Kit!$D$16+R30*Kit!$D$17+S30*Kit!$D$18+T30*Kit!$D$6+U30*Kit!$D$11+V30*Kit!$D$8+W30*Kit!$D$12+X30*Kit!$D$13+Y30*Kit!$D$14 -> 30.7676 | AA30: =P30*Kit!$E$15+Q30*Kit!$E$16+R30*Kit!$E$17+S30*Kit!$E$18+T30*Kit!$E$6+U30*Kit!$E$11+V30*Kit!$E$8+W30*Kit!$E$12+X30*Kit!$E$13+Y30*Kit!$E$14 -> 568.8456 | AB30: =K30*J30/1000 -> 8.93288 | AC30: =N30/M30 -> 2.3588889 | AD30: ilha, checkout, mesa de demonstração — vê-se por cima
A31: 300×754-3-médio | B31: 300×754 | C31: 287 | D31: 717 | E31: 3 | F31: médio · 270×5 | G31: 5 | H31: 0 | I31: 0 | J31: =G31+H31+1 -> 6 | K31: =2*Parametros!$C$6+(E31-1)*Parametros!$C$7+E31*(D31-Parametros!$C$13) -> 2233.22 | L31: =IF(I31>0,K31+2*Parametros!$C$10,K31) -> 2233.22 | M31: =C31+2*(Parametros!$C$8-Parametros!$C$5) -> 372.26 | N31: =Parametros!$C$11+(J31+IF(I31>0,1,0))*Parametros!$C$9+G31*(270-Parametros!$C$13)+H31*(513-Parametros!$C$13)+IF(I31>0,I31-Parametros!$C$13,0) -> 1401.88 | O31: =Parametros!$C$11+J31*Parametros!$C$9+G31*(270-Parametros!$C$13)+H31*(513-Parametros!$C$13)+Parametros!$C$12/2 -> 1409.38 | P31: =4*J31 -> 24 | Q31: =2*(E31-1)*(J31+IF(I31>0,1,0)) -> 24 | R31: =IF(I31>0,4,0) -> 0 | S31: =2*(E31+1) -> 8 | T31: =E31*J31 -> 18 | U31: =2*E31*J31+IF(I31>0,2*E31,0) -> 36 | V31: =(E31+1)*J31 -> 24 | W31: =2*(E31+1)*(G31+IF(I31=270,1,0)) -> 40 | X31: =2*(E31+1)*(H31+IF(I31=513,1,0)) -> 0 | Y31: =2*(E31+1) -> 8 | Z31: =P31*Kit!$D$15+Q31*Kit!$D$16+R31*Kit!$D$17+S31*Kit!$D$18+T31*Kit!$D$6+U31*Kit!$D$11+V31*Kit!$D$8+W31*Kit!$D$12+X31*Kit!$D$13+Y31*Kit!$D$14 -> 46.337 | AA31: =P31*Kit!$E$15+Q31*Kit!$E$16+R31*Kit!$E$17+S31*Kit!$E$18+T31*Kit!$E$6+U31*Kit!$E$11+V31*Kit!$E$8+W31*Kit!$E$12+X31*Kit!$E$13+Y31*Kit!$E$14 -> 856.8464 | AB31: =K31*J31/1000 -> 13.39932 | AC31: =N31/M31 -> 3.7658626 | AD31: gôndola de miolo, ponta
... A34: 300×754-3-arara | B34: 300×754 | C34: 287 | D34: 717 | E34: 3 | F34: arara · 513·513 + coroa 513 | G34: 0 | H34: 2 | I34: 513 | J34: =G34+H34+1 -> 3 | K34: =2*Parametros!$C$6+(E34-1)*Parametros!$C$7+E34*(D34-Parametros!$C$13) -> 2233.22 | L34: =IF(I34>0,K34+2*Parametros!$C$10,K34) -> 2277.06 | M34: =C34+2*(Parametros!$C$8-Parametros!$C$5) -> 372.26 | N34: =Parametros!$C$11+(J34+IF(I34>0,1,0))*Parametros!$C$9+G34*(270-Parametros!$C$13)+H34*(513-Parametros!$C$13)+IF(I34>0,I34-Parametros!$C$13,0) -> 1607.12 | O34: =Parametros!$C$11+J34*Parametros!$C$9+G34*(270-Parametros!$C$13)+H34*(513-Parametros!$C$13)+Parametros!$C$12/2 -> 1109.74 | P34: =4*J34 -> 12 | Q34: =2*(E34-1)*(J34+IF(I34>0,1,0)) -> 16 | R34: =IF(I34>0,4,0) -> 4 | S34: =2*(E34+1) -> 8 | T34: =E34*J34 -> 9 | U34: =2*E34*J34+IF(I34>0,2*E34,0) -> 24 | V34: =(E34+1)*J34 -> 12 | W34: =2*(E34+1)*(G34+IF(I34=270,1,0)) -> 0 | X34: =2*(E34+1)*(H34+IF(I34=513,1,0)) -> 24 | Y34: =2*(E34+1) -> 8 | Z34: =P34*Kit!$D$15+Q34*Kit!$D$16+R34*Kit!$D$17+S34*Kit!$D$18+T34*Kit!$D$6+U34*Kit!$D$11+V34*Kit!$D$8+W34*Kit!$D$12+X34*Kit!$D$13+Y34*Kit!$D$14 -> 26.1193 | AA34: =P34*Kit!$E$15+Q34*Kit!$E$16+R34*Kit!$E$17+S34*Kit!$E$18+T34*Kit!$E$6+U34*Kit!$E$11+V34*Kit!$E$8+W34*Kit!$E$12+X34*Kit!$E$13+Y34*Kit!$E$14 -> 480.9662 | AB34: =K34*J34/1000 -> 6.69966 | AC34: =N34/M34 -> 4.3171977 | AD34: arara e gancheira: a peça L fecha o topo sem prateleira
A35: 460×754-1-baixo | B35: 460×754 | C35: 415 | D35: 717 | E35: 1 | F35: baixo · 270×3 | G35: 3 | H35: 0 | I35: 0 | J35: =G35+H35+1 -> 4 | K35: =2*Parametros!$C$6+(E35-1)*Parametros!$C$7+E35*(D35-Parametros!$C$13) -> 759.02 | L35: =IF(I35>0,K35+2*Parametros!$C$10,K35) -> 759.02 | M35: =C35+2*(Parametros!$C$8-Parametros!$C$5) -> 500.26 | N35: =Parametros!$C$11+(J35+IF(I35>0,1,0))*Parametros!$C$9+G35*(270-Parametros!$C$13)+H35*(513-Parametros!$C$13)+IF(I35>0,I35-Parametros!$C$13,0) -> 878.12 | O35: =Parametros!$C$11+J35*Parametros!$C$9+G35*(270-Parametros!$C$13)+H35*(513-Parametros!$C$13)+Parametros!$C$12/2 -> 885.62 | P35: =4*J35 -> 16 | Q35: =2*(E35-1)*(J35+IF(I35>0,1,0)) -> 0 | R35: =IF(I35>0,4,0) -> 0 | S35: =2*(E35+1) -> 4 | T35: =E35*J35 -> 4 | U35: =2*E35*J35+IF(I35>0,2*E35,0) -> 8 | V35: =(E35+1)*J35 -> 8 | W35: =2*(E35+1)*(G35+IF(I35=270,1,0)) -> 12 | X35: =2*(E35+1)*(H35+IF(I35=513,1,0)) -> 0 | Y35: =2*(E35+1) -> 4 | Z35: =P35*Kit!$D$15+Q35*Kit!$D$16+R35*Kit!$D$17+S35*Kit!$D$18+T35*Kit!$D$7+U35*Kit!$D$11+V35*Kit!$D$9+W35*Kit!$D$12+X35*Kit!$D$13+Y35*Kit!$D$14 -> 15.12 | AA35: =P35*Kit!$E$15+Q35*Kit!$E$16+R35*Kit!$E$17+S35*Kit!$E$18+T35*Kit!$E$7+U35*Kit!$E$11+V35*Kit!$E$9+W35*Kit!$E$12+X35*Kit!$E$13+Y35*Kit!$E$14 -> 280.4076 | AB35: =K35*J35/1000 -> 3.03608 | AC35: =N35/M35 -> 1.7553272 | AD35: ilha, checkout, mesa de demonstração — vê-se por cima
A36: 460×754-1-médio | B36: 460×754 | C36: 415 | D36: 717 | E36: 1 | F36: médio · 270×5 | G36: 5 | H36: 0 | I36: 0 | J36: =G36+H36+1 -> 6 | K36: =2*Parametros!$C$6+(E36-1)*Parametros!$C$7+E36*(D36-Parametros!$C$13) -> 759.02 | L36: =IF(I36>0,K36+2*Parametros!$C$10,K36) -> 759.02 | M36: =C36+2*(Parametros!$C$8-Parametros!$C$5) -> 500.26 | N36: =Parametros!$C$11+(J36+IF(I36>0,1,0))*Parametros!$C$9+G36*(270-Parametros!$C$13)+H36*(513-Parametros!$C$13)+IF(I36>0,I36-Parametros!$C$13,0) -> 1401.88 | O36: =Parametros!$C$11+J36*Parametros!$C$9+G36*(270-Parametros!$C$13)+H36*(513-Parametros!$C$13)+Parametros!$C$12/2 -> 1409.38 | P36: =4*J36 -> 24 | Q36: =2*(E36-1)*(J36+IF(I36>0,1,0)) -> 0 | R36: =IF(I36>0,4,0) -> 0 | S36: =2*(E36+1) -> 4 | T36: =E36*J36 -> 6 | U36: =2*E36*J36+IF(I36>0,2*E36,0) -> 12 | V36: =(E36+1)*J36 -> 12 | W36: =2*(E36+1)*(G36+IF(I36=270,1,0)) -> 20 | X36: =2*(E36+1)*(H36+IF(I36=513,1,0)) -> 0 | Y36: =2*(E36+1) -> 4 | Z36: =P36*Kit!$D$15+Q36*Kit!$D$16+R36*Kit!$D$17+S36*Kit!$D$18+T36*Kit!$D$7+U36*Kit!$D$11+V36*Kit!$D$9+W36*Kit!$D$12+X36*Kit!$D$13+Y36*Kit!$D$14 -> 22.7728 | AA36: =P36*Kit!$E$15+Q36*Kit!$E$16+R36*Kit!$E$17+S36*Kit!$E$18+T36*Kit!$E$7+U36*Kit!$E$11+V36*Kit!$E$9+W36*Kit!$E$12+X36*Kit!$E$13+Y36*Kit!$E$14 -> 422.4004 | AB36: =K36*J36/1000 -> 4.55412 | AC36: =N36/M36 -> 2.8023028 | AD36: gôndola de miolo, ponta
A37: 460×754-1-alto | B37: 460×754 | C37: 415 | D37: 717 | E37: 1 | F37: alto · 270×6 | G37: 6 | H37: 0 | I37: 0 | J37: =G37+H37+1 -> 7 | K37: =2*Parametros!$C$6+(E37-1)*Parametros!$C$7+E37*(D37-Parametros!$C$13) -> 759.02 | L37: =IF(I37>0,K37+2*Parametros!$C$10,K37) -> 759.02 | M37: =C37+2*(Parametros!$C$8-Parametros!$C$5) -> 500.26 | N37: =Parametros!$C$11+(J37+IF(I37>0,1,0))*Parametros!$C$9+G37*(270-Parametros!$C$13)+H37*(513-Parametros!$C$13)+IF(I37>0,I37-Parametros!$C$13,0) -> 1663.76 | O37: =Parametros!$C$11+J37*Parametros!$C$9+G37*(270-Parametros!$C$13)+H37*(513-Parametros!$C$13)+Parametros!$C$12/2 -> 1671.26 | P37: =4*J37 -> 28 | Q37: =2*(E37-1)*(J37+IF(I37>0,1,0)) -> 0 | R37: =IF(I37>0,4,0) -> 0 | S37: =2*(E37+1) -> 4 | T37: =E37*J37 -> 7 | U37: =2*E37*J37+IF(I37>0,2*E37,0) -> 14 | V37: =(E37+1)*J37 -> 14 | W37: =2*(E37+1)*(G37+IF(I37=270,1,0)) -> 24 | X37: =2*(E37+1)*(H37+IF(I37=513,1,0)) -> 0 | Y37: =2*(E37+1) -> 4 | Z37: =P37*Kit!$D$15+Q37*Kit!$D$16+R37*Kit!$D$17+S37*Kit!$D$18+T37*Kit!$D$7+U37*Kit!$D$11+V37*Kit!$D$9+W37*Kit!$D$12+X37*Kit!$D$13+Y37*Kit!$D$14 -> 26.5992 | AA37: =P37*Kit!$E$15+Q37*Kit!$E$16+R37*Kit!$E$17+S37*Kit!$E$18+T37*Kit!$E$7+U37*Kit!$E$11+V37*Kit!$E$9+W37*Kit!$E$12+X37*Kit!$E$13+Y37*Kit!$E$14 -> 493.3968 | AB37: =K37*J37/1000 -> 5.31314 | AC37: =N37/M37 -> 3.3257906 | AD37: parede: duas prateleiras na zona dos olhos
A38: 460×754-1-alto-fundo | B38: 460×754 | C38: 415 | D38: 717 | E38: 1 | F38: alto-fundo · 513·513·270·270 | G38: 2 | H38: 2 | I38: 0 | J38: =G38+H38+1 -> 5 | K38: =2*Parametros!$C$6+(E38-1)*Parametros!$C$7+E38*(D38-Parametros!$C$13) -> 759.02 | L38: =IF(I38>0,K38+2*Parametros!$C$10,K38) -> 759.02 | M38: =C38+2*(Parametros!$C$8-Parametros!$C$5) -> 500.26 | N38: =Parametros!$C$11+(J38+IF(I38>0,1,0))*Parametros!$C$9+G38*(270-Parametros!$C$13)+H38*(513-Parametros!$C$13)+IF(I38>0,I38-Parametros!$C$13,0) -> 1626 | O38: =Parametros!$C$11+J38*Parametros!$C$9+G38*(270-Parametros!$C$13)+H38*(513-Parametros!$C$13)+Parametros!$C$12/2 -> 1633.5 | P38: =4*J38 -> 20 | Q38: =2*(E38-1)*(J38+IF(I38>0,1,0)) -> 0 | R38: =IF(I38>0,4,0) -> 0 | S38: =2*(E38+1) -> 4 | T38: =E38*J38 -> 5 | U38: =2*E38*J38+IF(I38>0,2*E38,0) -> 10 | V38: =(E38+1)*J38 -> 10 | W38: =2*(E38+1)*(G38+IF(I38=270,1,0)) -> 8 | X38: =2*(E38+1)*(H38+IF(I38=513,1,0)) -> 8 | Y38: =2*(E38+1) -> 4 | Z38: =P38*Kit!$D$15+Q38*Kit!$D$16+R38*Kit!$D$17+S38*Kit!$D$18+T38*Kit!$D$7+U38*Kit!$D$11+V38*Kit!$D$9+W38*Kit!$D$12+X38*Kit!$D$13+Y38*Kit!$D$14 -> 19.3864 | AA38: =P38*Kit!$E$15+Q38*Kit!$E$16+R38*Kit!$E$17+S38*Kit!$E$18+T38*Kit!$E$7+U38*Kit!$E$11+V38*Kit!$E$9+W38*Kit!$E$12+X38*Kit!$E$13+Y38*Kit!$E$14 -> 359.7752 | AB38: =K38*J38/1000 -> 3.7951 | AC38: =N38/M38 -> 3.2503098 | AD38: parede de banho/lavanderia: vão de 490 embaixo para lixeira e cesto
A39: 460×754-1-arara | B39: 460×754 | C39: 415 | D39: 717 | E39: 1 | F39: arara · 513·513 + coroa 513 | G39: 0 | H39: 2 | I39: 513 | J39: =G39+H39+1 -> 3 | K39: =2*Parametros!$C$6+(E39-1)*Parametros!$C$7+E39*(D39-Parametros!$C$13) -> 759.02 | L39: =IF(I39>0,K39+2*Parametros!$C$10,K39) -> 802.86 | M39: =C39+2*(Parametros!$C$8-Parametros!$C$5) -> 500.26 | N39: =Parametros!$C$11+(J39+IF(I39>0,1,0))*Parametros!$C$9+G39*(270-Parametros!$C$13)+H39*(513-Parametros!$C$13)+IF(I39>0,I39-Parametros!$C$13,0) -> 1607.12 | O39: =Parametros!$C$11+J39*Parametros!$C$9+G39*(270-Parametros!$C$13)+H39*(513-Parametros!$C$13)+Parametros!$C$12/2 -> 1109.74 | P39: =4*J39 -> 12 | Q39: =2*(E39-1)*(J39+IF(I39>0,1,0)) -> 0 | R39: =IF(I39>0,4,0) -> 4 | S39: =2*(E39+1) -> 4 | T39: =E39*J39 -> 3 | U39: =2*E39*J39+IF(I39>0,2*E39,0) -> 8 | V39: =(E39+1)*J39 -> 6 | W39: =2*(E39+1)*(G39+IF(I39=270,1,0)) -> 0 | X39: =2*(E39+1)*(H39+IF(I39=513,1,0)) -> 12 | Y39: =2*(E39+1) -> 4 | Z39: =P39*Kit!$D$15+Q39*Kit!$D$16+R39*Kit!$D$17+S39*Kit!$D$18+T39*Kit!$D$7+U39*Kit!$D$11+V39*Kit!$D$9+W39*Kit!$D$12+X39*Kit!$D$13+Y39*Kit!$D$14 -> 12.6504 | AA39: =P39*Kit!$E$15+Q39*Kit!$E$16+R39*Kit!$E$17+S39*Kit!$E$18+T39*Kit!$E$7+U39*Kit!$E$11+V39*Kit!$E$9+W39*Kit!$E$12+X39*Kit!$E$13+Y39*Kit!$E$14 -> 233.9946 | AB39: =K39*J39/1000 -> 2.27706 | AC39: =N39/M39 -> 3.2125695 | AD39: arara e gancheira: a peça L fecha o topo sem prateleira
A40: 460×754-2-baixo | B40: 460×754 | C40: 415 | D40: 717 | E40: 2 | F40: baixo · 270×3 | G40: 3 | H40: 0 | I40: 0 | J40: =G40+H40+1 -> 4 | K40: =2*Parametros!$C$6+(E40-1)*Parametros!$C$7+E40*(D40-Parametros!$C$13) -> 1496.12 | L40: =IF(I40>0,K40+2*Parametros!$C$10,K40) -> 1496.12 | M40: =C40+2*(Parametros!$C$8-Parametros!$C$5) -> 500.26 | N40: =Parametros!$C$11+(J40+IF(I40>0,1,0))*Parametros!$C$9+G40*(270-Parametros!$C$13)+H40*(513-Parametros!$C$13)+IF(I40>0,I40-Parametros!$C$13,0) -> 878.12 | O40: =Parametros!$C$11+J40*Parametros!$C$9+G40*(270-Parametros!$C$13)+H40*(513-Parametros!$C$13)+Parametros!$C$12/2 -> 885.62 | P40: =4*J40 -> 16 | Q40: =2*(E40-1)*(J40+IF(I40>0,1,0)) -> 8 | R40: =IF(I40>0,4,0) -> 0 | S40: =2*(E40+1) -> 6 | T40: =E40*J40 -> 8 | U40: =2*E40*J40+IF(I40>0,2*E40,0) -> 16 | V40: =(E40+1)*J40 -> 12 | W40: =2*(E40+1)*(G40+IF(I40=270,1,0)) -> 18 | X40: =2*(E40+1)*(H40+IF(I40=513,1,0)) -> 0 | Y40: =2*(E40+1) -> 6 | Z40: =P40*Kit!$D$15+Q40*Kit!$D$16+R40*Kit!$D$17+S40*Kit!$D$18+T40*Kit!$D$7+U40*Kit!$D$11+V40*Kit!$D$9+W40*Kit!$D$12+X40*Kit!$D$13+Y40*Kit!$D$14 -> 29.2124 | AA40: =P40*Kit!$E$15+Q40*Kit!$E$16+R40*Kit!$E$17+S40*Kit!$E$18+T40*Kit!$E$7+U40*Kit!$E$11+V40*Kit!$E$9+W40*Kit!$E$12+X40*Kit!$E$13+Y40*Kit!$E$14 -> 543.9162 | AB40: =K40*J40/1000 -> 5.98448 | AC40: =N40/M40 -> 1.7553272 | AD40: ilha, checkout, mesa de demonstração — vê-se por cima
A41: 460×754-2-médio | B41: 460×754 | C41: 415 | D41: 717 | E41: 2 | F41: médio · 270×5 | G41: 5 | H41: 0 | I41: 0 | J41: =G41+H41+1 -> 6 | K41: =2*Parametros!$C$6+(E41-1)*Parametros!$C$7+E41*(D41-Parametros!$C$13) -> 1496.12 | L41: =IF(I41>0,K41+2*Parametros!$C$10,K41) -> 1496.12 | M41: =C41+2*(Parametros!$C$8-Parametros!$C$5) -> 500.26 | N41: =Parametros!$C$11+(J41+IF(I41>0,1,0))*Parametros!$C$9+G41*(270-Parametros!$C$13)+H41*(513-Parametros!$C$13)+IF(I41>0,I41-Parametros!$C$13,0) -> 1401.88 | O41: =Parametros!$C$11+J41*Parametros!$C$9+G41*(270-Parametros!$C$13)+H41*(513-Parametros!$C$13)+Parametros!$C$12/2 -> 1409.38 | P41: =4*J41 -> 24 | Q41: =2*(E41-1)*(J41+IF(I41>0,1,0)) -> 12 | R41: =IF(I41>0,4,0) -> 0 | S41: =2*(E41+1) -> 6 | T41: =E41*J41 -> 12 | U41: =2*E41*J41+IF(I41>0,2*E41,0) -> 24 | V41: =(E41+1)*J41 -> 18 | W41: =2*(E41+1)*(G41+IF(I41=270,1,0)) -> 30 | X41: =2*(E41+1)*(H41+IF(I41=513,1,0)) -> 0 | Y41: =2*(E41+1) -> 6 | Z41: =P41*Kit!$D$15+Q41*Kit!$D$16+R41*Kit!$D$17+S41*Kit!$D$18+T41*Kit!$D$7+U41*Kit!$D$11+V41*Kit!$D$9+W41*Kit!$D$12+X41*Kit!$D$13+Y41*Kit!$D$14 -> 43.9578 | AA41: =P41*Kit!$E$15+Q41*Kit!$E$16+R41*Kit!$E$17+S41*Kit!$E$18+T41*Kit!$E$7+U41*Kit!$E$11+V41*Kit!$E$9+W41*Kit!$E$12+X41*Kit!$E$13+Y41*Kit!$E$14 -> 818.5578 | AB41: =K41*J41/1000 -> 8.97672 | AC41: =N41/M41 -> 2.8023028 | AD41: gôndola de miolo, ponta
A42: 460×754-2-alto | B42: 460×754 | C42: 415 | D42: 717 | E42: 2 | F42: alto · 270×6 | G42: 6 | H42: 0 | I42: 0 | J42: =G42+H42+1 -> 7 | K42: =2*Parametros!$C$6+(E42-1)*Parametros!$C$7+E42*(D42-Parametros!$C$13) -> 1496.12 | L42: =IF(I42>0,K42+2*Parametros!$C$10,K42) -> 1496.12 | M42: =C42+2*(Parametros!$C$8-Parametros!$C$5) -> 500.26 | N42: =Parametros!$C$11+(J42+IF(I42>0,1,0))*Parametros!$C$9+G42*(270-Parametros!$C$13)+H42*(513-Parametros!$C$13)+IF(I42>0,I42-Parametros!$C$13,0) -> 1663.76 | O42: =Parametros!$C$11+J42*Parametros!$C$9+G42*(270-Parametros!$C$13)+H42*(513-Parametros!$C$13)+Parametros!$C$12/2 -> 1671.26 | P42: =4*J42 -> 28 | Q42: =2*(E42-1)*(J42+IF(I42>0,1,0)) -> 14 | R42: =IF(I42>0,4,0) -> 0 | S42: =2*(E42+1) -> 6 | T42: =E42*J42 -> 14 | U42: =2*E42*J42+IF(I42>0,2*E42,0) -> 28 | V42: =(E42+1)*J42 -> 21 | W42: =2*(E42+1)*(G42+IF(I42=270,1,0)) -> 36 | X42: =2*(E42+1)*(H42+IF(I42=513,1,0)) -> 0 | Y42: =2*(E42+1) -> 6 | Z42: =P42*Kit!$D$15+Q42*Kit!$D$16+R42*Kit!$D$17+S42*Kit!$D$18+T42*Kit!$D$7+U42*Kit!$D$11+V42*Kit!$D$9+W42*Kit!$D$12+X42*Kit!$D$13+Y42*Kit!$D$14 -> 51.3305 | AA42: =P42*Kit!$E$15+Q42*Kit!$E$16+R42*Kit!$E$17+S42*Kit!$E$18+T42*Kit!$E$7+U42*Kit!$E$11+V42*Kit!$E$9+W42*Kit!$E$12+X42*Kit!$E$13+Y42*Kit!$E$14 -> 955.8786 | AB42: =K42*J42/1000 -> 10.47284 | AC42: =N42/M42 -> 3.3257906 | AD42: parede: duas prateleiras na zona dos olhos
A43: 460×754-2-alto-fundo | B43: 460×754 | C43: 415 | D43: 717 | E43: 2 | F43: alto-fundo · 513·513·270·270 | G43: 2 | H43: 2 | I43: 0 | J43: =G43+H43+1 -> 5 | K43: =2*Parametros!$C$6+(E43-1)*Parametros!$C$7+E43*(D43-Parametros!$C$13) -> 1496.12 | L43: =IF(I43>0,K43+2*Parametros!$C$10,K43) -> 1496.12 | M43: =C43+2*(Parametros!$C$8-Parametros!$C$5) -> 500.26 | N43: =Parametros!$C$11+(J43+IF(I43>0,1,0))*Parametros!$C$9+G43*(270-Parametros!$C$13)+H43*(513-Parametros!$C$13)+IF(I43>0,I43-Parametros!$C$13,0) -> 1626 | O43: =Parametros!$C$11+J43*Parametros!$C$9+G43*(270-Parametros!$C$13)+H43*(513-Parametros!$C$13)+Parametros!$C$12/2 -> 1633.5 | P43: =4*J43 -> 20 | Q43: =2*(E43-1)*(J43+IF(I43>0,1,0)) -> 10 | R43: =IF(I43>0,4,0) -> 0 | S43: =2*(E43+1) -> 6 | T43: =E43*J43 -> 10 | U43: =2*E43*J43+IF(I43>0,2*E43,0) -> 20 | V43: =(E43+1)*J43 -> 15 | W43: =2*(E43+1)*(G43+IF(I43=270,1,0)) -> 12 | X43: =2*(E43+1)*(H43+IF(I43=513,1,0)) -> 12 | Y43: =2*(E43+1) -> 6 | Z43: =P43*Kit!$D$15+Q43*Kit!$D$16+R43*Kit!$D$17+S43*Kit!$D$18+T43*Kit!$D$7+U43*Kit!$D$11+V43*Kit!$D$9+W43*Kit!$D$12+X43*Kit!$D$13+Y43*Kit!$D$14 -> 37.2451 | AA43: =P43*Kit!$E$15+Q43*Kit!$E$16+R43*Kit!$E$17+S43*Kit!$E$18+T43*Kit!$E$7+U43*Kit!$E$11+V43*Kit!$E$9+W43*Kit!$E$12+X43*Kit!$E$13+Y43*Kit!$E$14 -> 693.7938 | AB43: =K43*J43/1000 -> 7.4806 | AC43: =N43/M43 -> 3.2503098 | AD43: parede de banho/lavanderia: vão de 490 embaixo para lixeira e cesto
A44: 460×754-2-arara | B44: 460×754 | C44: 415 | D44: 717 | E44: 2 | F44: arara · 513·513 + coroa 513 | G44: 0 | H44: 2 | I44: 513 | J44: =G44+H44+1 -> 3 | K44: =2*Parametros!$C$6+(E44-1)*Parametros!$C$7+E44*(D44-Parametros!$C$13) -> 1496.12 | L44: =IF(I44>0,K44+2*Parametros!$C$10,K44) -> 1539.96 | M44: =C44+2*(Parametros!$C$8-Parametros!$C$5) -> 500.26 | N44: =Parametros!$C$11+(J44+IF(I44>0,1,0))*Parametros!$C$9+G44*(270-Parametros!$C$13)+H44*(513-Parametros!$C$13)+IF(I44>0,I44-Parametros!$C$13,0) -> 1607.12 | O44: =Parametros!$C$11+J44*Parametros!$C$9+G44*(270-Parametros!$C$13)+H44*(513-Parametros!$C$13)+Parametros!$C$12/2 -> 1109.74 | P44: =4*J44 -> 12 | Q44: =2*(E44-1)*(J44+IF(I44>0,1,0)) -> 8 | R44: =IF(I44>0,4,0) -> 4 | S44: =2*(E44+1) -> 6 | T44: =E44*J44 -> 6 | U44: =2*E44*J44+IF(I44>0,2*E44,0) -> 16 | V44: =(E44+1)*J44 -> 9 | W44: =2*(E44+1)*(G44+IF(I44=270,1,0)) -> 0 | X44: =2*(E44+1)*(H44+IF(I44=513,1,0)) -> 18 | Y44: =2*(E44+1) -> 6 | Z44: =P44*Kit!$D$15+Q44*Kit!$D$16+R44*Kit!$D$17+S44*Kit!$D$18+T44*Kit!$D$7+U44*Kit!$D$11+V44*Kit!$D$9+W44*Kit!$D$12+X44*Kit!$D$13+Y44*Kit!$D$14 -> 24.0863 | AA44: =P44*Kit!$E$15+Q44*Kit!$E$16+R44*Kit!$E$17+S44*Kit!$E$18+T44*Kit!$E$7+U44*Kit!$E$11+V44*Kit!$E$9+W44*Kit!$E$12+X44*Kit!$E$13+Y44*Kit!$E$14 -> 446.9476 | AB44: =K44*J44/1000 -> 4.48836 | AC44: =N44/M44 -> 3.2125695 | AD44: arara e gancheira: a peça L fecha o topo sem prateleira
A45: 460×754-3-baixo | B45: 460×754 | C45: 415 | D45: 717 | E45: 3 | F45: baixo · 270×3 | G45: 3 | H45: 0 | I45: 0 | J45: =G45+H45+1 -> 4 | K45: =2*Parametros!$C$6+(E45-1)*Parametros!$C$7+E45*(D45-Parametros!$C$13) -> 2233.22 | L45: =IF(I45>0,K45+2*Parametros!$C$10,K45) -> 2233.22 | M45: =C45+2*(Parametros!$C$8-Parametros!$C$5) -> 500.26 | N45: =Parametros!$C$11+(J45+IF(I45>0,1,0))*Parametros!$C$9+G45*(270-Parametros!$C$13)+H45*(513-Parametros!$C$13)+IF(I45>0,I45-Parametros!$C$13,0) -> 878.12 | O45: =Parametros!$C$11+J45*Parametros!$C$9+G45*(270-Parametros!$C$13)+H45*(513-Parametros!$C$13)+Parametros!$C$12/2 -> 885.62 | P45: =4*J45 -> 16 | Q45: =2*(E45-1)*(J45+IF(I45>0,1,0)) -> 16 | R45: =IF(I45>0,4,0) -> 0 | S45: =2*(E45+1) -> 8 | T45: =E45*J45 -> 12 | U45: =2*E45*J45+IF(I45>0,2*E45,0) -> 24 | V45: =(E45+1)*J45 -> 16 | W45: =2*(E45+1)*(G45+IF(I45=270,1,0)) -> 24 | X45: =2*(E45+1)*(H45+IF(I45=513,1,0)) -> 0 | Y45: =2*(E45+1) -> 8 | Z45: =P45*Kit!$D$15+Q45*Kit!$D$16+R45*Kit!$D$17+S45*Kit!$D$18+T45*Kit!$D$7+U45*Kit!$D$11+V45*Kit!$D$9+W45*Kit!$D$12+X45*Kit!$D$13+Y45*Kit!$D$14 -> 43.3048 | AA45: =P45*Kit!$E$15+Q45*Kit!$E$16+R45*Kit!$E$17+S45*Kit!$E$18+T45*Kit!$E$7+U45*Kit!$E$11+V45*Kit!$E$9+W45*Kit!$E$12+X45*Kit!$E$13+Y45*Kit!$E$14 -> 807.4248 | AB45: =K45*J45/1000 -> 8.93288 | AC45: =N45/M45 -> 1.7553272 | AD45: ilha, checkout, mesa de demonstração — vê-se por cima
...

Sheet Showroom
A1: Montagem sugerida do showroom só com módulos N = 1 (zero cruzeta)
A2: Escolha o ID na coluna B (lista da aba Modulos) e a quantidade; o resto é fórmula. Quando a cruzeta existir, troque paredes fixas por N = 3 e a conta se refaz.
A4: Onde | B4: ID do módulo | C4: Qtd | D4: Comprimento montado (mm) | E4: Corrida livre (mm) | F4: Folga (mm) | G4: Custo (R$) | H4: Frente (m) | I4: Massa (kg) | J4: Cruzetas
A5: Paredão sul · cozinha | B5: 300×754-1-alto | C5: 17 | D5: =C5*INDEX(Modulos!$K$5:$K$49,MATCH($B5,Modulos!$A$5:$A$49,0)) -> 12903.34 | E5: 13350 | F5: =E5-D5 -> 446.66 | G5: =C5*INDEX(Modulos!$AA$5:$AA$49,MATCH($B5,Modulos!$A$5:$A$49,0)) -> 5978.1146 | H5: =C5*INDEX(Modulos!$AB$5:$AB$49,MATCH($B5,Modulos!$A$5:$A$49,0)) -> 90.32338 | I5: =C5*INDEX(Modulos!$Z$5:$Z$49,MATCH($B5,Modulos!$A$5:$A$49,0)) -> 325.5585 | J5: =C5*INDEX(Modulos!$Q$5:$Q$49,MATCH($B5,Modulos!$A$5:$A$49,0)) -> 0
A6: Paredão norte · organização | B6: 300×754-1-alto | C6: 8 | D6: =C6*INDEX(Modulos!$K$5:$K$49,MATCH($B6,Modulos!$A$5:$A$49,0)) -> 6072.16 | E6: 6100 | F6: =E6-D6 -> 27.84 | G6: =C6*INDEX(Modulos!$AA$5:$AA$49,MATCH($B6,Modulos!$A$5:$A$49,0)) -> 2813.2304 | H6: =C6*INDEX(Modulos!$AB$5:$AB$49,MATCH($B6,Modulos!$A$5:$A$49,0)) -> 42.50512 | I6: =C6*INDEX(Modulos!$Z$5:$Z$49,MATCH($B6,Modulos!$A$5:$A$49,0)) -> 153.204 | J6: =C6*INDEX(Modulos!$Q$5:$Q$49,MATCH($B6,Modulos!$A$5:$A$49,0)) -> 0
A7: Paredão do fundo · banho e lavanderia | B7: 460×754-1-alto-fundo | C7: 9 | D7: =C7*INDEX(Modulos!$K$5:$K$49,MATCH($B7,Modulos!$A$5:$A$49,0)) -> 6831.18 | E7: 6873 | F7: =E7-D7 -> 41.82 | G7: =C7*INDEX(Modulos!$AA$5:$AA$49,MATCH($B7,Modulos!$A$5:$A$49,0)) -> 3237.9768 | H7: =C7*INDEX(Modulos!$AB$5:$AB$49,MATCH($B7,Modulos!$A$5:$A$49,0)) -> 34.1559 | I7: =C7*INDEX(Modulos!$Z$5:$Z$49,MATCH($B7,Modulos!$A$5:$A$49,0)) -> 174.4776 | J7: =C7*INDEX(Modulos!$Q$5:$Q$49,MATCH($B7,Modulos!$A$5:$A$49,0)) -> 0
A8: Parede de entrada · frasqueiras | B8: 300×754-1-alto-fundo | C8: 8 | D8: =C8*INDEX(Modulos!$K$5:$K$49,MATCH($B8,Modulos!$A$5:$A$49,0)) -> 6072.16 | E8: 6548 | F8: =E8-D8 -> 475.84 | G8: =C8*INDEX(Modulos!$AA$5:$AA$49,MATCH($B8,Modulos!$A$5:$A$49,0)) -> 2068.2416 | H8: =C8*INDEX(Modulos!$AB$5:$AB$49,MATCH($B8,Modulos!$A$5:$A$49,0)) -> 30.3608 | I8: =C8*INDEX(Modulos!$Z$5:$Z$49,MATCH($B8,Modulos!$A$5:$A$49,0)) -> 112.5272 | J8: =C8*INDEX(Modulos!$Q$5:$Q$49,MATCH($B8,Modulos!$A$5:$A$49,0)) -> 0
A9: Folga caixa–pilar | B9: 300×450-1-alto | C9: 1 | D9: =C9*INDEX(Modulos!$K$5:$K$49,MATCH($B9,Modulos!$A$5:$A$49,0)) -> 457.02 | E9: 700 | F9: =E9-D9 -> 242.98 | G9: =C9*INDEX(Modulos!$AA$5:$AA$49,MATCH($B9,Modulos!$A$5:$A$49,0)) -> 232.1267 | H9: =C9*INDEX(Modulos!$AB$5:$AB$49,MATCH($B9,Modulos!$A$5:$A$49,0)) -> 3.19914 | I9: =C9*INDEX(Modulos!$Z$5:$Z$49,MATCH($B9,Modulos!$A$5:$A$49,0)) -> 12.8701 | J9: =C9*INDEX(Modulos!$Q$5:$Q$49,MATCH($B9,Modulos!$A$5:$A$49,0)) -> 0
A10: Ilha 1 · 2 × 2 costa a costa | B10: 460×754-1-baixo | C10: 4 | D10: =C10*INDEX(Modulos!$K$5:$K$49,MATCH($B10,Modulos!$A$5:$A$49,0)) -> 3036.08 | G10: =C10*INDEX(Modulos!$AA$5:$AA$49,MATCH($B10,Modulos!$A$5:$A$49,0)) -> 1121.6304 | H10: =C10*INDEX(Modulos!$AB$5:$AB$49,MATCH($B10,Modulos!$A$5:$A$49,0)) -> 12.14432 | I10: =C10*INDEX(Modulos!$Z$5:$Z$49,MATCH($B10,Modulos!$A$5:$A$49,0)) -> 60.48 | J10: =C10*INDEX(Modulos!$Q$5:$Q$49,MATCH($B10,Modulos!$A$5:$A$49,0)) -> 0
A11: Ilha 2 · 2 × 2 costa a costa | B11: 460×754-1-baixo | C11: 4 | D11: =C11*INDEX(Modulos!$K$5:$K$49,MATCH($B11,Modulos!$A$5:$A$49,0)) -> 3036.08 | G11: =C11*INDEX(Modulos!$AA$5:$AA$49,MATCH($B11,Modulos!$A$5:$A$49,0)) -> 1121.6304 | H11: =C11*INDEX(Modulos!$AB$5:$AB$49,MATCH($B11,Modulos!$A$5:$A$49,0)) -> 12.14432 | I11: =C11*INDEX(Modulos!$Z$5:$Z$49,MATCH($B11,Modulos!$A$5:$A$49,0)) -> 60.48 | J11: =C11*INDEX(Modulos!$Q$5:$Q$49,MATCH($B11,Modulos!$A$5:$A$49,0)) -> 0
A12: Corredor de checkout · 2 lados × 3 | B12: 300×754-1-baixo | C12: 6 | D12: =C12*INDEX(Modulos!$K$5:$K$49,MATCH($B12,Modulos!$A$5:$A$49,0)) -> 4554.12 | G12: =C12*INDEX(Modulos!$AA$5:$AA$49,MATCH($B12,Modulos!$A$5:$A$49,0)) -> 1196.4696 | H12: =C12*INDEX(Modulos!$AB$5:$AB$49,MATCH($B12,Modulos!$A$5:$A$49,0)) -> 18.21648 | I12: =C12*INDEX(Modulos!$Z$5:$Z$49,MATCH($B12,Modulos!$A$5:$A$49,0)) -> 65.1816 | J12: =C12*INDEX(Modulos!$Q$5:$Q$49,MATCH($B12,Modulos!$A$5:$A$49,0)) -> 0
A13: Arara Nitron-Mob no miolo | B13: 300×754-1-arara | C13: 2 | D13: =C13*INDEX(Modulos!$K$5:$K$49,MATCH($B13,Modulos!$A$5:$A$49,0)) -> 1518.04 | G13: =C13*INDEX(Modulos!$AA$5:$AA$49,MATCH($B13,Modulos!$A$5:$A$49,0)) -> 346.4952 | H13: =C13*INDEX(Modulos!$AB$5:$AB$49,MATCH($B13,Modulos!$A$5:$A$49,0)) -> 4.55412 | I13: =C13*INDEX(Modulos!$Z$5:$Z$49,MATCH($B13,Modulos!$A$5:$A$49,0)) -> 18.9162 | J13: =C13*INDEX(Modulos!$Q$5:$Q$49,MATCH($B13,Modulos!$A$5:$A$49,0)) -> 0
A14: TOTAL | C14: =SUM(C5:C13) -> 59 | G14: =SUM(G5:G13) -> 18115.916 | H14: =SUM(H5:H13) -> 247.60358 | I14: =SUM(I5:I13) -> 983.6952 | J14: =SUM(J5:J13) -> 0
A16: Peças a comprar / injetar
A17: Peça | B17: Quantidade | C17: Massa (kg) | D17: Custo (R$)
A18: Trizeta | B18: =SUMPRODUCT($C$5:$C$13,IFERROR(INDEX(Modulos!$P$5:$P$49,MATCH($B$5:$B$13,Modulos!$A$5:$A$49,0)),0)) -> 1316 | C18: =B18*Kit!$D$15 -> 58.2988 | D18: =B18*Kit!$E$15 -> 509.95
A19: Cruzeta | B19: =SUMPRODUCT($C$5:$C$13,IFERROR(INDEX(Modulos!$Q$5:$Q$49,MATCH($B$5:$B$13,Modulos!$A$5:$A$49,0)),0)) -> 0 | C19: =B19*Kit!$D$16 -> 0 | D19: =B19*Kit!$E$16 -> 0
A20: Peça L | B20: =SUMPRODUCT($C$5:$C$13,IFERROR(INDEX(Modulos!$R$5:$R$49,MATCH($B$5:$B$13,Modulos!$A$5:$A$49,0)),0)) -> 8 | C20: =B20*Kit!$D$17 -> 0.256 | D20: =B20*Kit!$E$17 -> 2.4024
A21: Tampa | B21: =SUMPRODUCT($C$5:$C$13,IFERROR(INDEX(Modulos!$S$5:$S$49,MATCH($B$5:$B$13,Modulos!$A$5:$A$49,0)),0)) -> 236 | C21: =B21*Kit!$D$18 -> 0.2596 | D21: =B21*Kit!$E$18 -> 2.2892
A22: Painel 300×450 | B22: =SUMPRODUCT($C$5:$C$13,--(LEFT($B$5:$B$13,7)="300×450"),IFERROR(INDEX(Modulos!$T$5:$T$49,MATCH($B$5:$B$13,Modulos!$A$5:$A$49,0)),0)) -> 7 | C22: =B22*Kit!$D$5 -> 7.8813 | D22: =B22*Kit!$E$5 -> 149.9813
A23: Painel 300×754 | B23: =SUMPRODUCT($C$5:$C$13,--(LEFT($B$5:$B$13,7)="300×754"),IFERROR(INDEX(Modulos!$T$5:$T$49,MATCH($B$5:$B$13,Modulos!$A$5:$A$49,0)),0)) -> 245 | C23: =B23*Kit!$D$6 -> 462.1925 | D23: =B23*Kit!$E$6 -> 8795.549
